Workbook

Sheet TOTAL TEMPORADA 25-26
A2: TOTAL TEMPORADA | C2: 22
A3: PARTIDOS | C3: 9
B4: GANADOS | C4: 7
B5: PERDIDOS | C5: 1
B7: EMPATADOS | C7: 1 | E7: JUGADORES | O7: LANZAMIENTOS | AQ7: VALORACIÓN POSITVIA | AX7: VALORACION NEGATIVA | BE7: SANCIONES DISCIPLINARIAS
C8: =SUM(C4:C7) -> 9 | E8: Dorsal | F8: Nombre | G8: Posición | H8: Partidos Presente | I8: Faltas | J8: Tiempo Medio Jugado Minutos | K8: % SOBRE EL TOTAL | L8: Valoracion Cualitativa | N8: Valoración Cuantitativa | O8: TOTAL | R8: 9 metros | Y8: Extremo | AE8: 6 metros/Ctq | AK8: 7 metros | AQ8: POSITIVO | AR8: Asistencia/. Bloqueo | AS8: Fuerza 7M/2' | AT8: Recupera | AU8: Buena DEF | AV8: Blocaje | AW8: NEGATIVO | AX8: PASE | AY8: RECEPCION | AZ8: PASOS | BA8: DOBLES | BB8: PISAR | BC8: F. ATAQUE | BD8: FALLO DEF. | BE8: A | BF8: 2' | BG8: 2' | BH8: Ex. | BI8: D.
L9: DefeNsa | M9: Ataque | O9: % | P9: Lanz. | Q9: Gol | R9: % | S9: Lanz | T9: Gol | U9: Para | V9: Poste | W9: Fuera | X9: Bloq | Y9: % | Z9: Lanz | AA9: Gol | AB9: Parada | AC9: Poste | AD9: Fuera | AE9: % | AF9: Lanz | AG9: Gol | AH9: Parada | AI9: Poste | AJ9: Fuera | AK9: % | AL9: Lanz | AM9: Gol | AN9: Para | AO9: Poste | AP9: Fuera
F10: ALEJO | H10: 9 | I10: 0 | J10: =('J1'!I10+'J2'!I10+'J3'!I10+'J4'!I9+'J5'!I10+'J6'!I10+'J7'!I10+'J8'!I10+'J9'!I10+'J10'!I10++'J11'!I10+'J12'!I10+'J13'!I10+'J14'!I10+'J15'!I10+'J16'!I10+'J17'!I10+'J18'!I10+'J19'!I10+'J20'!I10+'J21'!I10+'J22'!I10)/H10 -> 33.666667 | K10: =J10/60 -> 0.56111111 | L10: =('J1'!J10+'J2'!J10+'J3'!J10+'J4'!J10+'J5'!J10+'J6'!J10+'J7'!J10+'J8'!J10+'J9'!J10+'J10'!J10++'J11'!J10+'J12'!J10+'J13'!J10+'J14'!J10+'J15'!J10+'J16'!J10+'J17'!J10+'J18'!J10+'J19'!J10+'J20'!J10+'J21'!J10+'J22'!J10)/$C$3 -> 0 | M10: =('J1'!K10+'J2'!K10+'J3'!K10+'J4'!K10+'J5'!K10+'J6'!K10+'J7'!K10+'J8'!K10+'J9'!K10+'J10'!K10++'J11'!K10+'J12'!K10+'J13'!K10+'J14'!K10+'J15'!K10+'J16'!K10+'J17'!K10+'J18'!K10+'J19'!K10+'J20'!K10+'J21'!K10+'J22'!K10)/$C$3 -> 0 | N10: =('J1'!L10+'J2'!L10+'J3'!L10+'J4'!L10+'J5'!L10+'J6'!L10+'J7'!L10+'J8'!L10+'J9'!L10+'J10'!L10+'J11'!L10+'J12'!L10+'J13'!L10+'J14'!L10+'J15'!L10+'J16'!L10+'J17'!L10+'J18'!L10+'J19'!L10+'J20'!L10+'J21'!L10+'J22'!L10)/$C$3 -> 1.2222222 | O10: =IFERROR(Q10/P10,"") -> 0.61333333 | P10: =SUM(T10:X10)+SUM(AG10:AJ10)+SUM(AM10:AP10)+SUM(AA10:AD10) -> 75 | Q10: =T10+AG10+AM10+AA10 -> 46 | R10: =IF(SUM(T10:X10)=0,"",T10/SUM(T10:X10)) -> 0.51851852 | S10: =SUM(T10:X10) -> 27 | T10: ='J1'!R10+'J2'!R10+'J3'!R10+'J4'!R10+'J5'!R10+'J6'!R10+'J7'!R10+'J8'!R10+'J9'!R10+'J10'!R10++'J11'!R10+'J12'!R10+'J13'!R10+'J14'!R10+'J15'!R10+'J16'!R10+'J17'!R10+'J18'!R10+'J19'!R10+'J20'!R10+'J21'!R10+'J22'!R10 -> 14 | U10: ='J1'!S10+'J2'!S10+'J3'!S10+'J4'!S10+'J5'!S10+'J6'!S10+'J7'!S10+'J8'!S10+'J9'!S10+'J10'!S10++'J11'!S10+'J12'!S10+'J13'!S10+'J14'!S10+'J15'!S10+'J16'!S10+'J17'!S10+'J18'!S10+'J19'!S10+'J20'!S10+'J21'!S10+'J22'!S10 -> 6 | V10: ='J1'!T10+'J2'!T10+'J3'!T10+'J4'!T10+'J5'!T10+'J6'!T10+'J7'!T10+'J8'!T10+'J9'!T10+'J10'!T10++'J11'!T10+'J12'!T10+'J13'!T10+'J14'!T10+'J15'!T10+'J16'!T10+'J17'!T10+'J18'!T10+'J19'!T10+'J20'!T10+'J21'!T10+'J22'!T10 -> 2 | W10: ='J1'!U10+'J2'!U10+'J3'!U10+'J4'!U10+'J5'!U10+'J6'!U10+'J7'!U10+'J8'!U10+'J9'!U10+'J10'!U10++'J11'!U10+'J12'!U10+'J13'!U10+'J14'!U10+'J15'!U10+'J16'!U10+'J17'!U10+'J18'!U10+'J19'!U10+'J20'!U10+'J21'!U10+'J22'!U10 -> 5 | X10: ='J1'!V10+'J2'!V10+'J3'!V10+'J4'!V10+'J5'!V10+'J6'!V10+'J7'!V10+'J8'!V10+'J9'!V10+'J10'!V10++'J11'!V10+'J12'!V10+'J13'!V10+'J14'!V10+'J15'!V10+'J16'!V10+'J17'!V10+'J18'!V10+'J19'!V10+'J20'!V10+'J21'!V10+'J22'!V10 -> 0 | Y10: =IFERROR(AA10/SUM(AA10:AD10), "") -> 0.55555556 | Z10: =SUM(AA10:AD10) -> 9 | AA10: ='J1'!Y10+'J2'!Y10+'J3'!Y10+'J4'!Y10+'J5'!Y10+'J6'!Y10+'J7'!Y10+'J8'!Y10+'J9'!Y10+'J10'!Y10++'J11'!Y10+'J12'!Y10+'J13'!Y10+'J14'!Y10+'J15'!Y10+'J16'!Y10+'J17'!Y10+'J18'!Y10+'J19'!Y10+'J20'!Y10+'J21'!Y10+'J22'!Y10 -> 5 | AB10: ='J1'!Z10+'J2'!Z10+'J3'!Z10+'J4'!Z10+'J5'!Z10+'J6'!Z10+'J7'!Z10+'J8'!Z10+'J9'!Z10+'J10'!Z10++'J11'!Z10+'J12'!Z10+'J13'!Z10+'J14'!Z10+'J15'!Z10+'J16'!Z10+'J17'!Z10+'J18'!Z10+'J19'!Z10+'J20'!Z10+'J21'!Z10+'J22'!Z10 -> 3 | AC10: ='J1'!AA10+'J2'!AA10+'J3'!AA10+'J4'!AA10+'J5'!AA10+'J6'!AA10+'J7'!AA10+'J8'!AA10+'J9'!AA10+'J10'!AA10++'J11'!AA10+'J12'!AA10+'J13'!AA10+'J14'!AA10+'J15'!AA10+'J16'!AA10+'J17'!AA10+'J18'!AA10+'J19'!AA10+'J20'!AA10+'J21'!AA10+'J22'!AA10 -> 0 | AD10: ='J1'!AB10+'J2'!AB10+'J3'!AB10+'J4'!AB10+'J5'!AB10+'J6'!AB10+'J7'!AB10+'J8'!AB10+'J9'!AB10+'J10'!AB10++'J11'!AB10+'J12'!AB10+'J13'!AB10+'J14'!AB10+'J15'!AB10+'J16'!AB10+'J17'!AB10+'J18'!AB10+'J19'!AB10+'J20'!AB10+'J21'!AB10+'J22'!AB10 -> 1 | AE10: =IFERROR(AG10/SUM(AG10:AJ10), "") -> 0.69444444 | AF10: =SUM(AG10:AJ10) -> 36 | AG10: ='J1'!AE10+'J2'!AE10+'J3'!AE10+'J4'!AE10+'J5'!AE10+'J6'!AE10+'J7'!AE10+'J8'!AE10+'J9'!AE10+'J10'!AE10++'J11'!AE10+'J12'!AE10+'J13'!AE10+'J14'!AE10+'J15'!AE10+'J16'!AE10+'J17'!AE10+'J18'!AE10+'J19'!AE10+'J20'!AE10+'J21'!AE10+'J22'!AE10 -> 25 | AH10: ='J1'!AF10+'J2'!AF10+'J3'!AF10+'J4'!AF10+'J5'!AF10+'J6'!AF10+'J7'!AF10+'J8'!AF10+'J9'!AF10+'J10'!AF10++'J11'!AF10+'J12'!AF10+'J13'!AF10+'J14'!AF10+'J15'!AF10+'J16'!AF10+'J17'!AF10+'J18'!AF10+'J19'!AF10+'J20'!AF10+'J21'!AF10+'J22'!AF10 -> 4 | AI10: ='J1'!AG10+'J2'!AG10+'J3'!AG10+'J4'!AG10+'J5'!AG10+'J6'!AG10+'J7'!AG10+'J8'!AG10+'J9'!AG10+'J10'!AG10++'J11'!AG10+'J12'!AG10+'J13'!AG10+'J14'!AG10+'J15'!AG10+'J16'!AG10+'J17'!AG10+'J18'!AG10+'J19'!AG10+'J20'!AG10+'J21'!AG10+'J22'!AG10 -> 2 | AJ10: ='J1'!AH10+'J2'!AH10+'J3'!AH10+'J4'!AH10+'J5'!AH10+'J6'!AH10+'J7'!AH10+'J8'!AH10+'J9'!AH10+'J10'!AH10++'J11'!AH10+'J12'!AH10+'J13'!AH10+'J14'!AH10+'J15'!AH10+'J16'!AH10+'J17'!AH10+'J18'!AH10+'J19'!AH10+'J20'!AH10+'J21'!AH10+'J22'!AH10 -> 5 | AK10: =IFERROR(AM10/SUM(AM10:AP10), "") -> 0.66666667 | AL10: =SUM(AM10:AP10) -> 3 | AM10: ='J1'!AK10+'J2'!AK10+'J3'!AK10+'J4'!AK10+'J5'!AK10+'J6'!AK10+'J7'!AK10+'J8'!AK10+'J9'!AK10+'J10'!AK10++'J11'!AK10+'J12'!AK10+'J13'!AK10+'J14'!AK10+'J15'!AK10+'J16'!AK10+'J17'!AK10+'J18'!AK10+'J19'!AK10+'J20'!AK10+'J21'!AK10+'J22'!AK10 -> 2 | AN10: ='J1'!AL10+'J2'!AL10+'J3'!AL10+'J4'!AL10+'J5'!AL10+'J6'!AL10+'J7'!AL10+'J8'!AL10+'J9'!AL10+'J10'!AL10++'J11'!AL10+'J12'!AL10+'J13'!AL10+'J14'!AL10+'J15'!AL10+'J16'!AL10+'J17'!AL10+'J18'!AL10+'J19'!AL10+'J20'!AL10+'J21'!AL10+'J22'!AL10 -> 1 | AO10: ='J1'!AM10+'J2'!AM10+'J3'!AM10+'J4'!AM10+'J5'!AM10+'J6'!AM10+'J7'!AM10+'J8'!AM10+'J9'!AM10+'J10'!AM10++'J11'!AM10+'J12'!AM10+'J13'!AM10+'J14'!AM10+'J15'!AM10+'J16'!AM10+'J17'!AM10+'J18'!AM10+'J19'!AM10+'J20'!AM10+'J21'!AM10+'J22'!AM10 -> 0 | AP10: ='J1'!AN10+'J2'!AN10+'J3'!AN10+'J4'!AN10+'J5'!AN10+'J6'!AN10+'J7'!AN10+'J8'!AN10+'J9'!AN10+'J10'!AN10++'J11'!AN10+'J12'!AN10+'J13'!AN10+'J14'!AN10+'J15'!AN10+'J16'!AN10+'J17'!AN10+'J18'!AN10+'J19'!AN10+'J20'!AN10+'J21'!AN10+'J22'!AN10 -> 0 | AQ10: =AR10+AS10+AT10+0.5*AU10+0.5*AV10 -> 8.5 | AR10: ='J1'!AP10+'J2'!AP10+'J3'!AP10+'J4'!AP10+'J5'!AP10+'J6'!AP10+'J7'!AP10+'J8'!AP10+'J9'!AP10+'J10'!AP10++'J11'!AP10+'J12'!AP10+'J13'!AP10+'J14'!AP10+'J15'!AP10+'J16'!AP10+'J17'!AP10+'J18'!AP10+'J19'!AP10+'J20'!AP10+'J21'!AP10+'J22'!AP10 -> 0 | AS10: ='J1'!AQ10+'J2'!AQ10+'J3'!AQ10+'J4'!AQ10+'J5'!AQ10+'J6'!AQ10+'J7'!AQ10+'J8'!AQ10+'J9'!AQ10+'J10'!AQ10++'J11'!AQ10+'J12'!AQ10+'J13'!AQ10+'J14'!AQ10+'J15'!AQ10+'J16'!AQ10+'J17'!AQ10+'J18'!AQ10+'J19'!AQ10+'J20'!AQ10+'J21'!AQ10+'J22'!AQ10 -> 0 | AT10: ='J1'!AR10+'J2'!AR10+'J3'!AR10+'J4'!AR10+'J5'!AR10+'J6'!AR10+'J7'!AR10+'J8'!AR10+'J9'!AR10+'J10'!AR10++'J11'!AR10+'J12'!AR10+'J13'!AR10+'J14'!AR10+'J15'!AR10+'J16'!AR10+'J17'!AR10+'J18'!AR10+'J19'!AR10+'J20'!AR10+'J21'!AR10+'J22'!AR10 -> 8 | AU10: ='J1'!AS10+'J2'!AS10+'J3'!AS10+'J4'!AS10+'J5'!AS10+'J6'!AS10+'J7'!AS10+'J8'!AS10+'J9'!AS10+'J10'!AS10++'J11'!AS10+'J12'!AS10+'J13'!AS10+'J14'!AS10+'J15'!AS10+'J16'!AS10+'J17'!AS10+'J18'!AS10+'J19'!AS10+'J20'!AS10+'J21'!AS10+'J22'!AS10 -> 0 | AV10: ='J1'!AT10+'J2'!AT10+'J3'!AT10+'J4'!AT10+'J5'!AT10+'J6'!AT10+'J7'!AT10+'J8'!AT10+'J9'!AT10+'J10'!AT10++'J11'!AT10+'J12'!AT10+'J13'!AT10+'J14'!AT10+'J15'!AT10+'J16'!AT10+'J17'!AT10+'J18'!AT10+'J19'!AT10+'J20'!AT10+'J21'!AT10+'J22'!AT10 -> 1 | AW10: =AX10+AY10+AZ10+BA10+BB10+BC10+BD10+0.5*BE10+BF10+BG10+2*BH10+2*BI10 -> 10 | AX10: ='J1'!AV10+'J2'!AV10+'J3'!AV10+'J4'!AV10+'J5'!AV10+'J6'!AV10+'J7'!AV10+'J8'!AV10+'J9'!AV10+'J10'!AV10++'J11'!AV10+'J12'!AV10+'J13'!AV10+'J14'!AV10+'J15'!AV10+'J16'!AV10+'J17'!AV10+'J18'!AV10+'J19'!AV10+'J20'!AV10+'J21'!AV10+'J22'!AV10 -> 6 | AY10: ='J1'!AW10+'J2'!AW10+'J3'!AW10+'J4'!AW10+'J5'!AW10+'J6'!AW10+'J7'!AW10+'J8'!AW10+'J9'!AW10+'J10'!AW10++'J11'!AW10+'J12'!AW10+'J13'!AW10+'J14'!AW10+'J15'!AW10+'J16'!AW10+'J17'!AW10+'J18'!AW10+'J19'!AW10+'J20'!AW10+'J21'!AW10+'J22'!AW10 -> 0 | AZ10: ='J1'!AX10+'J2'!AX10+'J3'!AX10+'J4'!AX10+'J5'!AX10+'J6'!AX10+'J7'!AX10+'J8'!AX10+'J9'!AX10+'J10'!AX10++'J11'!AX10+'J12'!AX10+'J13'!AX10+'J14'!AX10+'J15'!AX10+'J16'!AX10+'J17'!AX10+'J18'!AX10+'J19'!AX10+'J20'!AX10+'J21'!AX10+'J22'!AX10 -> 2 | BA10: ='J1'!AY10+'J2'!AY10+'J3'!AY10+'J4'!AY10+'J5'!AY10+'J6'!AY10+'J7'!AY10+'J8'!AY10+'J9'!AY10+'J10'!AY10++'J11'!AY10+'J12'!AY10+'J13'!AY10+'J14'!AY10+'J15'!AY10+'J16'!AY10+'J17'!AY10+'J18'!AY10+'J19'!AY10+'J20'!AY10+'J21'!AY10+'J22'!AY10 -> 1 | BB10: ='J1'!AZ10+'J2'!AZ10+'J3'!AZ10+'J4'!AZ10+'J5'!AZ10+'J6'!AZ10+'J7'!AZ10+'J8'!AZ10+'J9'!AZ10+'J10'!AZ10++'J11'!AZ10+'J12'!AZ10+'J13'!AZ10+'J14'!AZ10+'J15'!AZ10+'J16'!AZ10+'J17'!AZ10+'J18'!AZ10+'J19'!AZ10+'J20'!AZ10+'J21'!AZ10+'J22'!AZ10 -> 0 | BC10: ='J1'!BA10+'J2'!BA10+'J3'!BA10+'J4'!BA10+'J5'!BA10+'J6'!BA10+'J7'!BA10+'J8'!BA10+'J9'!BA10+'J10'!BA10++'J11'!BA10+'J12'!BA10+'J13'!BA10+'J14'!BA10+'J15'!BA10+'J16'!BA10+'J17'!BA10+'J18'!BA10+'J19'!BA10+'J20'!BA10+'J21'!BA10+'J22'!BA10 -> 0 | BD10: ='J1'!BB10+'J2'!BB10+'J3'!BB10+'J4'!BB10+'J5'!BB10+'J6'!BB10+'J7'!BB10+'J8'!BB10+'J9'!BB10+'J10'!BB10++'J11'!BB10+'J12'!BB10+'J13'!BB10+'J14'!BB10+'J15'!BB10+'J16'!BB10+'J17'!BB10+'J18'!BB10+'J19'!BB10+'J20'!BB10+'J21'!BB10+'J22'!BB10 -> 0 | BE10: ='J1'!BC10+'J2'!BC10+'J3'!BC10+'J4'!BC10+'J5'!BC10+'J6'!BC10+'J7'!BC10+'J8'!BC10+'J9'!BC10+'J10'!BC10++'J11'!BC10+'J12'!BC10+'J13'!BC10+'J14'!BC10+'J15'!BC10+'J16'!BC10+'J17'!BC10+'J18'!BC10+'J19'!BC10+'J20'!BC10+'J21'!BC10+'J22'!BC10 -> 0 | ... BI10: ='J1'!BG10+'J2'!BG10+'J3'!BG10+'J4'!BG10+'J5'!BG10+'J6'!BG10+'J7'!BG10+'J8'!BG10+'J9'!BG10+'J10'!BG10++'J11'!BG10+'J12'!BG10+'J13'!BG10+'J14'!BG10+'J15'!BG10+'J16'!BG10+'J17'!BG10+'J18'!BG10+'J19'!BG10+'J20'!BG10+'J21'!BG10+'J22'!BG10 -> 0
F11: CHRISTIAN | H11: 7 | I11: 2 | J11: =('J1'!I11+'J2'!I11+'J3'!I11+'J4'!I10+'J5'!I11+'J6'!I11+'J7'!I11+'J8'!I11+'J9'!I11+'J10'!I11++'J11'!I11+'J12'!I11+'J13'!I11+'J14'!I11+'J15'!I11+'J16'!I11+'J17'!I11+'J18'!I11+'J19'!I11+'J20'!I11+'J21'!I11+'J22'!I11)/H11 -> 35.857143 | K11: =J11/60 -> 0.59761905 | L11: =('J1'!J11+'J2'!J11+'J3'!J11+'J4'!J11+'J5'!J11+'J6'!J11+'J7'!J11+'J8'!J11+'J9'!J11+'J10'!J11++'J11'!J11+'J12'!J11+'J13'!J11+'J14'!J11+'J15'!J11+'J16'!J11+'J17'!J11+'J18'!J11+'J19'!J11+'J20'!J11+'J21'!J11+'J22'!J11)/$C$3 -> 0 | M11: =('J1'!K11+'J2'!K11+'J3'!K11+'J4'!K11+'J5'!K11+'J6'!K11+'J7'!K11+'J8'!K11+'J9'!K11+'J10'!K11++'J11'!K11+'J12'!K11+'J13'!K11+'J14'!K11+'J15'!K11+'J16'!K11+'J17'!K11+'J18'!K11+'J19'!K11+'J20'!K11+'J21'!K11+'J22'!K11)/$C$3 -> 0 | N11: =('J1'!L11+'J2'!L11+'J3'!L11+'J4'!L11+'J5'!L11+'J6'!L11+'J7'!L11+'J8'!L11+'J9'!L11+'J10'!L11+'J11'!L11+'J12'!L11+'J13'!L11+'J14'!L11+'J15'!L11+'J16'!L11+'J17'!L11+'J18'!L11+'J19'!L11+'J20'!L11+'J21'!L11+'J22'!L11)/$C$3 -> 0.55555556 | O11: =IFERROR(Q11/P11,"") -> 0.65384615 | P11: =SUM(T11:X11)+SUM(AG11:AJ11)+SUM(AM11:AP11)+SUM(AA11:AD11) -> 26 | Q11: =T11+AG11+AM11+AA11 -> 17 | R11: =IF(SUM(T11:X11)=0,"",T11/SUM(T11:X11)) | S11: =SUM(T11:X11) -> 0 | T11: ='J1'!R11+'J2'!R11+'J3'!R11+'J4'!R11+'J5'!R11+'J6'!R11+'J7'!R11+'J8'!R11+'J9'!R11+'J10'!R11++'J11'!R11+'J12'!R11+'J13'!R11+'J14'!R11+'J15'!R11+'J16'!R11+'J17'!R11+'J18'!R11+'J19'!R11+'J20'!R11+'J21'!R11+'J22'!R11 -> 0 | U11: ='J1'!S11+'J2'!S11+'J3'!S11+'J4'!S11+'J5'!S11+'J6'!S11+'J7'!S11+'J8'!S11+'J9'!S11+'J10'!S11++'J11'!S11+'J12'!S11+'J13'!S11+'J14'!S11+'J15'!S11+'J16'!S11+'J17'!S11+'J18'!S11+'J19'!S11+'J20'!S11+'J21'!S11+'J22'!S11 -> 0 | V11: ='J1'!T11+'J2'!T11+'J3'!T11+'J4'!T11+'J5'!T11+'J6'!T11+'J7'!T11+'J8'!T11+'J9'!T11+'J10'!T11++'J11'!T11+'J12'!T11+'J13'!T11+'J14'!T11+'J15'!T11+'J16'!T11+'J17'!T11+'J18'!T11+'J19'!T11+'J20'!T11+'J21'!T11+'J22'!T11 -> 0 | W11: ='J1'!U11+'J2'!U11+'J3'!U11+'J4'!U11+'J5'!U11+'J6'!U11+'J7'!U11+'J8'!U11+'J9'!U11+'J10'!U11++'J11'!U11+'J12'!U11+'J13'!U11+'J14'!U11+'J15'!U11+'J16'!U11+'J17'!U11+'J18'!U11+'J19'!U11+'J20'!U11+'J21'!U11+'J22'!U11 -> 0 | X11: ='J1'!V11+'J2'!V11+'J3'!V11+'J4'!V11+'J5'!V11+'J6'!V11+'J7'!V11+'J8'!V11+'J9'!V11+'J10'!V11++'J11'!V11+'J12'!V11+'J13'!V11+'J14'!V11+'J15'!V11+'J16'!V11+'J17'!V11+'J18'!V11+'J19'!V11+'J20'!V11+'J21'!V11+'J22'!V11 -> 0 | Y11: =IFERROR(AA11/SUM(AA11:AD11), "") -> 0.625 | Z11: =SUM(AA11:AD11) -> 24 | AA11: ='J1'!Y11+'J2'!Y11+'J3'!Y11+'J4'!Y11+'J5'!Y11+'J6'!Y11+'J7'!Y11+'J8'!Y11+'J9'!Y11+'J10'!Y11++'J11'!Y11+'J12'!Y11+'J13'!Y11+'J14'!Y11+'J15'!Y11+'J16'!Y11+'J17'!Y11+'J18'!Y11+'J19'!Y11+'J20'!Y11+'J21'!Y11+'J22'!Y11 -> 15 | AB11: ='J1'!Z11+'J2'!Z11+'J3'!Z11+'J4'!Z11+'J5'!Z11+'J6'!Z11+'J7'!Z11+'J8'!Z11+'J9'!Z11+'J10'!Z11++'J11'!Z11+'J12'!Z11+'J13'!Z11+'J14'!Z11+'J15'!Z11+'J16'!Z11+'J17'!Z11+'J18'!Z11+'J19'!Z11+'J20'!Z11+'J21'!Z11+'J22'!Z11 -> 7 | AC11: ='J1'!AA11+'J2'!AA11+'J3'!AA11+'J4'!AA11+'J5'!AA11+'J6'!AA11+'J7'!AA11+'J8'!AA11+'J9'!AA11+'J10'!AA11++'J11'!AA11+'J12'!AA11+'J13'!AA11+'J14'!AA11+'J15'!AA11+'J16'!AA11+'J17'!AA11+'J18'!AA11+'J19'!AA11+'J20'!AA11+'J21'!AA11+'J22'!AA11 -> 2 | AD11: ='J1'!AB11+'J2'!AB11+'J3'!AB11+'J4'!AB11+'J5'!AB11+'J6'!AB11+'J7'!AB11+'J8'!AB11+'J9'!AB11+'J10'!AB11++'J11'!AB11+'J12'!AB11+'J13'!AB11+'J14'!AB11+'J15'!AB11+'J16'!AB11+'J17'!AB11+'J18'!AB11+'J19'!AB11+'J20'!AB11+'J21'!AB11+'J22'!AB11 -> 0 | AE11: =IFERROR(AG11/SUM(AG11:AJ11), "") -> 1 | AF11: =SUM(AG11:AJ11) -> 2 | AG11: ='J1'!AE11+'J2'!AE11+'J3'!AE11+'J4'!AE11+'J5'!AE11+'J6'!AE11+'J7'!AE11+'J8'!AE11+'J9'!AE11+'J10'!AE11++'J11'!AE11+'J12'!AE11+'J13'!AE11+'J14'!AE11+'J15'!AE11+'J16'!AE11+'J17'!AE11+'J18'!AE11+'J19'!AE11+'J20'!AE11+'J21'!AE11+'J22'!AE11 -> 2 | AH11: ='J1'!AF11+'J2'!AF11+'J3'!AF11+'J4'!AF11+'J5'!AF11+'J6'!AF11+'J7'!AF11+'J8'!AF11+'J9'!AF11+'J10'!AF11++'J11'!AF11+'J12'!AF11+'J13'!AF11+'J14'!AF11+'J15'!AF11+'J16'!AF11+'J17'!AF11+'J18'!AF11+'J19'!AF11+'J20'!AF11+'J21'!AF11+'J22'!AF11 -> 0 | AI11: ='J1'!AG11+'J2'!AG11+'J3'!AG11+'J4'!AG11+'J5'!AG11+'J6'!AG11+'J7'!AG11+'J8'!AG11+'J9'!AG11+'J10'!AG11++'J11'!AG11+'J12'!AG11+'J13'!AG11+'J14'!AG11+'J15'!AG11+'J16'!AG11+'J17'!AG11+'J18'!AG11+'J19'!AG11+'J20'!AG11+'J21'!AG11+'J22'!AG11 -> 0 | AJ11: ='J1'!AH11+'J2'!AH11+'J3'!AH11+'J4'!AH11+'J5'!AH11+'J6'!AH11+'J7'!AH11+'J8'!AH11+'J9'!AH11+'J10'!AH11++'J11'!AH11+'J12'!AH11+'J13'!AH11+'J14'!AH11+'J15'!AH11+'J16'!AH11+'J17'!AH11+'J18'!AH11+'J19'!AH11+'J20'!AH11+'J21'!AH11+'J22'!AH11 -> 0 | AK11: =IFERROR(AM11/SUM(AM11:AP11), "") | AL11: =SUM(AM11:AP11) -> 0 | AM11: ='J1'!AK11+'J2'!AK11+'J3'!AK11+'J4'!AK11+'J5'!AK11+'J6'!AK11+'J7'!AK11+'J8'!AK11+'J9'!AK11+'J10'!AK11++'J11'!AK11+'J12'!AK11+'J13'!AK11+'J14'!AK11+'J15'!AK11+'J16'!AK11+'J17'!AK11+'J18'!AK11+'J19'!AK11+'J20'!AK11+'J21'!AK11+'J22'!AK11 -> 0 | AN11: ='J1'!AL11+'J2'!AL11+'J3'!AL11+'J4'!AL11+'J5'!AL11+'J6'!AL11+'J7'!AL11+'J8'!AL11+'J9'!AL11+'J10'!AL11++'J11'!AL11+'J12'!AL11+'J13'!AL11+'J14'!AL11+'J15'!AL11+'J16'!AL11+'J17'!AL11+'J18'!AL11+'J19'!AL11+'J20'!AL11+'J21'!AL11+'J22'!AL11 -> 0 | AO11: ='J1'!AM11+'J2'!AM11+'J3'!AM11+'J4'!AM11+'J5'!AM11+'J6'!AM11+'J7'!AM11+'J8'!AM11+'J9'!AM11+'J10'!AM11++'J11'!AM11+'J12'!AM11+'J13'!AM11+'J14'!AM11+'J15'!AM11+'J16'!AM11+'J17'!AM11+'J18'!AM11+'J19'!AM11+'J20'!AM11+'J21'!AM11+'J22'!AM11 -> 0 | AP11: ='J1'!AN11+'J2'!AN11+'J3'!AN11+'J4'!AN11+'J5'!AN11+'J6'!AN11+'J7'!AN11+'J8'!AN11+'J9'!AN11+'J10'!AN11++'J11'!AN11+'J12'!AN11+'J13'!AN11+'J14'!AN11+'J15'!AN11+'J16'!AN11+'J17'!AN11+'J18'!AN11+'J19'!AN11+'J20'!AN11+'J21'!AN11+'J22'!AN11 -> 0 | AQ11: =SUM(AR11:AV11) -> 1 | AR11: ='J1'!AP11+'J2'!AP11+'J3'!AP11+'J4'!AP11+'J5'!AP11+'J6'!AP11+'J7'!AP11+'J8'!AP11+'J9'!AP11+'J10'!AP11++'J11'!AP11+'J12'!AP11+'J13'!AP11+'J14'!AP11+'J15'!AP11+'J16'!AP11+'J17'!AP11+'J18'!AP11+'J19'!AP11+'J20'!AP11+'J21'!AP11+'J22'!AP11 -> 0 | AS11: ='J1'!AQ11+'J2'!AQ11+'J3'!AQ11+'J4'!AQ11+'J5'!AQ11+'J6'!AQ11+'J7'!AQ11+'J8'!AQ11+'J9'!AQ11+'J10'!AQ11++'J11'!AQ11+'J12'!AQ11+'J13'!AQ11+'J14'!AQ11+'J15'!AQ11+'J16'!AQ11+'J17'!AQ11+'J18'!AQ11+'J19'!AQ11+'J20'!AQ11+'J21'!AQ11+'J22'!AQ11 -> 0 | AT11: ='J1'!AR11+'J2'!AR11+'J3'!AR11+'J4'!AR11+'J5'!AR11+'J6'!AR11+'J7'!AR11+'J8'!AR11+'J9'!AR11+'J10'!AR11++'J11'!AR11+'J12'!AR11+'J13'!AR11+'J14'!AR11+'J15'!AR11+'J16'!AR11+'J17'!AR11+'J18'!AR11+'J19'!AR11+'J20'!AR11+'J21'!AR11+'J22'!AR11 -> 1 | AU11: ='J1'!AS11+'J2'!AS11+'J3'!AS11+'J4'!AS11+'J5'!AS11+'J6'!AS11+'J7'!AS11+'J8'!AS11+'J9'!AS11+'J10'!AS11++'J11'!AS11+'J12'!AS11+'J13'!AS11+'J14'!AS11+'J15'!AS11+'J16'!AS11+'J17'!AS11+'J18'!AS11+'J19'!AS11+'J20'!AS11+'J21'!AS11+'J22'!AS11 -> 0 | AV11: ='J1'!AT11+'J2'!AT11+'J3'!AT11+'J4'!AT11+'J5'!AT11+'J6'!AT11+'J7'!AT11+'J8'!AT11+'J9'!AT11+'J10'!AT11++'J11'!AT11+'J12'!AT11+'J13'!AT11+'J14'!AT11+'J15'!AT11+'J16'!AT11+'J17'!AT11+'J18'!AT11+'J19'!AT11+'J20'!AT11+'J21'!AT11+'J22'!AT11 -> 0 | AW11: =AX11+AY11+AZ11+BA11+BB11+BC11+BD11+0.5*BE11+BF11+BG11+2*BH11+2*BI11 -> 3 | AX11: ='J1'!AV11+'J2'!AV11+'J3'!AV11+'J4'!AV11+'J5'!AV11+'J6'!AV11+'J7'!AV11+'J8'!AV11+'J9'!AV11+'J10'!AV11++'J11'!AV11+'J12'!AV11+'J13'!AV11+'J14'!AV11+'J15'!AV11+'J16'!AV11+'J17'!AV11+'J18'!AV11+'J19'!AV11+'J20'!AV11+'J21'!AV11+'J22'!AV11 -> 1 | AY11: ='J1'!AW11+'J2'!AW11+'J3'!AW11+'J4'!AW11+'J5'!AW11+'J6'!AW11+'J7'!AW11+'J8'!AW11+'J9'!AW11+'J10'!AW11++'J11'!AW11+'J12'!AW11+'J13'!AW11+'J14'!AW11+'J15'!AW11+'J16'!AW11+'J17'!AW11+'J18'!AW11+'J19'!AW11+'J20'!AW11+'J21'!AW11+'J22'!AW11 -> 2 | AZ11: ='J1'!AX11+'J2'!AX11+'J3'!AX11+'J4'!AX11+'J5'!AX11+'J6'!AX11+'J7'!AX11+'J8'!AX11+'J9'!AX11+'J10'!AX11++'J11'!AX11+'J12'!AX11+'J13'!AX11+'J14'!AX11+'J15'!AX11+'J16'!AX11+'J17'!AX11+'J18'!AX11+'J19'!AX11+'J20'!AX11+'J21'!AX11+'J22'!AX11 -> 0 | BA11: ='J1'!AY11+'J2'!AY11+'J3'!AY11+'J4'!AY11+'J5'!AY11+'J6'!AY11+'J7'!AY11+'J8'!AY11+'J9'!AY11+'J10'!AY11++'J11'!AY11+'J12'!AY11+'J13'!AY11+'J14'!AY11+'J15'!AY11+'J16'!AY11+'J17'!AY11+'J18'!AY11+'J19'!AY11+'J20'!AY11+'J21'!AY11+'J22'!AY11 -> 0 | BB11: ='J1'!AZ11+'J2'!AZ11+'J3'!AZ11+'J4'!AZ11+'J5'!AZ11+'J6'!AZ11+'J7'!AZ11+'J8'!AZ11+'J9'!AZ11+'J10'!AZ11++'J11'!AZ11+'J12'!AZ11+'J13'!AZ11+'J14'!AZ11+'J15'!AZ11+'J16'!AZ11+'J17'!AZ11+'J18'!AZ11+'J19'!AZ11+'J20'!AZ11+'J21'!AZ11+'J22'!AZ11 -> 0 | BC11: ='J1'!BA11+'J2'!BA11+'J3'!BA11+'J4'!BA11+'J5'!BA11+'J6'!BA11+'J7'!BA11+'J8'!BA11+'J9'!BA11+'J10'!BA11++'J11'!BA11+'J12'!BA11+'J13'!BA11+'J14'!BA11+'J15'!BA11+'J16'!BA11+'J17'!BA11+'J18'!BA11+'J19'!BA11+'J20'!BA11+'J21'!BA11+'J22'!BA11 -> 0 | BD11: ='J1'!BB11+'J2'!BB11+'J3'!BB11+'J4'!BB11+'J5'!BB11+'J6'!BB11+'J7'!BB11+'J8'!BB11+'J9'!BB11+'J10'!BB11++'J11'!BB11+'J12'!BB11+'J13'!BB11+'J14'!BB11+'J15'!BB11+'J16'!BB11+'J17'!BB11+'J18'!BB11+'J19'!BB11+'J20'!BB11+'J21'!BB11+'J22'!BB11 -> 0 | BE11: ='J1'!BC11+'J2'!BC11+'J3'!BC11+'J4'!BC11+'J5'!BC11+'J6'!BC11+'J7'!BC11+'J8'!BC11+'J9'!BC11+'J10'!BC11++'J11'!BC11+'J12'!BC11+'J13'!BC11+'J14'!BC11+'J15'!BC11+'J16'!BC11+'J17'!BC11+'J18'!BC11+'J19'!BC11+'J20'!BC11+'J21'!BC11+'J22'!BC11 -> 0 | ... BI11: ='J1'!BG11+'J2'!BG11+'J3'!BG11+'J4'!BG11+'J5'!BG11+'J6'!BG11+'J7'!BG11+'J8'!BG11+'J9'!BG11+'J10'!BG11++'J11'!BG11+'J12'!BG11+'J13'!BG11+'J14'!BG11+'J15'!BG11+'J16'!BG11+'J17'!BG11+'J18'!BG11+'J19'!BG11+'J20'!BG11+'J21'!BG11+'J22'!BG11 -> 0
F12: DIEGO | H12: 9 | I12: 0 | J12: =('J1'!I12+'J2'!I12+'J3'!I12+'J4'!I11+'J5'!I12+'J6'!I12+'J7'!I12+'J8'!I12+'J9'!I12+'J10'!I12++'J11'!I12+'J12'!I12+'J13'!I12+'J14'!I12+'J15'!I12+'J16'!I12+'J17'!I12+'J18'!I12+'J19'!I12+'J20'!I12+'J21'!I12+'J22'!I12)/H12 -> 33.333333 | K12: =J12/60 -> 0.55555556 | L12: =('J1'!J12+'J2'!J12+'J3'!J12+'J4'!J12+'J5'!J12+'J6'!J12+'J7'!J12+'J8'!J12+'J9'!J12+'J10'!J12++'J11'!J12+'J12'!J12+'J13'!J12+'J14'!J12+'J15'!J12+'J16'!J12+'J17'!J12+'J18'!J12+'J19'!J12+'J20'!J12+'J21'!J12+'J22'!J12)/$C$3 -> 0 | M12: =('J1'!K12+'J2'!K12+'J3'!K12+'J4'!K12+'J5'!K12+'J6'!K12+'J7'!K12+'J8'!K12+'J9'!K12+'J10'!K12++'J11'!K12+'J12'!K12+'J13'!K12+'J14'!K12+'J15'!K12+'J16'!K12+'J17'!K12+'J18'!K12+'J19'!K12+'J20'!K12+'J21'!K12+'J22'!K12)/$C$3 -> 0 | N12: =('J1'!L12+'J2'!L12+'J3'!L12+'J4'!L12+'J5'!L12+'J6'!L12+'J7'!L12+'J8'!L12+'J9'!L12+'J10'!L12+'J11'!L12+'J12'!L12+'J13'!L12+'J14'!L12+'J15'!L12+'J16'!L12+'J17'!L12+'J18'!L12+'J19'!L12+'J20'!L12+'J21'!L12+'J22'!L12)/$C$3 -> -1.8333333 | O12: =IFERROR(Q12/P12,"") -> 0.51162791 | P12: =SUM(T12:X12)+SUM(AG12:AJ12)+SUM(AM12:AP12)+SUM(AA12:AD12) -> 43 | Q12: =T12+AG12+AM12+AA12 -> 22 | R12: =IF(SUM(T12:X12)=0,"",T12/SUM(T12:X12)) -> 1 | S12: =SUM(T12:X12) -> 1 | T12: ='J1'!R12+'J2'!R12+'J3'!R12+'J4'!R12+'J5'!R12+'J6'!R12+'J7'!R12+'J8'!R12+'J9'!R12+'J10'!R12++'J11'!R12+'J12'!R12+'J13'!R12+'J14'!R12+'J15'!R12+'J16'!R12+'J17'!R12+'J18'!R12+'J19'!R12+'J20'!R12+'J21'!R12+'J22'!R12 -> 1 | U12: ='J1'!S12+'J2'!S12+'J3'!S12+'J4'!S12+'J5'!S12+'J6'!S12+'J7'!S12+'J8'!S12+'J9'!S12+'J10'!S12++'J11'!S12+'J12'!S12+'J13'!S12+'J14'!S12+'J15'!S12+'J16'!S12+'J17'!S12+'J18'!S12+'J19'!S12+'J20'!S12+'J21'!S12+'J22'!S12 -> 0 | V12: ='J1'!T12+'J2'!T12+'J3'!T12+'J4'!T12+'J5'!T12+'J6'!T12+'J7'!T12+'J8'!T12+'J9'!T12+'J10'!T12++'J11'!T12+'J12'!T12+'J13'!T12+'J14'!T12+'J15'!T12+'J16'!T12+'J17'!T12+'J18'!T12+'J19'!T12+'J20'!T12+'J21'!T12+'J22'!T12 -> 0 | W12: ='J1'!U12+'J2'!U12+'J3'!U12+'J4'!U12+'J5'!U12+'J6'!U12+'J7'!U12+'J8'!U12+'J9'!U12+'J10'!U12++'J11'!U12+'J12'!U12+'J13'!U12+'J14'!U12+'J15'!U12+'J16'!U12+'J17'!U12+'J18'!U12+'J19'!U12+'J20'!U12+'J21'!U12+'J22'!U12 -> 0 | X12: ='J1'!V12+'J2'!V12+'J3'!V12+'J4'!V12+'J5'!V12+'J6'!V12+'J7'!V12+'J8'!V12+'J9'!V12+'J10'!V12++'J11'!V12+'J12'!V12+'J13'!V12+'J14'!V12+'J15'!V12+'J16'!V12+'J17'!V12+'J18'!V12+'J19'!V12+'J20'!V12+'J21'!V12+'J22'!V12 -> 0 | Y12: =IFERROR(AA12/SUM(AA12:AD12), "") -> 0.35294118 | Z12: =SUM(AA12:AD12) -> 17 | AA12: ='J1'!Y12+'J2'!Y12+'J3'!Y12+'J4'!Y12+'J5'!Y12+'J6'!Y12+'J7'!Y12+'J8'!Y12+'J9'!Y12+'J10'!Y12++'J11'!Y12+'J12'!Y12+'J13'!Y12+'J14'!Y12+'J15'!Y12+'J16'!Y12+'J17'!Y12+'J18'!Y12+'J19'!Y12+'J20'!Y12+'J21'!Y12+'J22'!Y12 -> 6 | AB12: ='J1'!Z12+'J2'!Z12+'J3'!Z12+'J4'!Z12+'J5'!Z12+'J6'!Z12+'J7'!Z12+'J8'!Z12+'J9'!Z12+'J10'!Z12++'J11'!Z12+'J12'!Z12+'J13'!Z12+'J14'!Z12+'J15'!Z12+'J16'!Z12+'J17'!Z12+'J18'!Z12+'J19'!Z12+'J20'!Z12+'J21'!Z12+'J22'!Z12 -> 7 | AC12: ='J1'!AA12+'J2'!AA12+'J3'!AA12+'J4'!AA12+'J5'!AA12+'J6'!AA12+'J7'!AA12+'J8'!AA12+'J9'!AA12+'J10'!AA12++'J11'!AA12+'J12'!AA12+'J13'!AA12+'J14'!AA12+'J15'!AA12+'J16'!AA12+'J17'!AA12+'J18'!AA12+'J19'!AA12+'J20'!AA12+'J21'!AA12+'J22'!AA12 -> 1 | AD12: ='J1'!AB12+'J2'!AB12+'J3'!AB12+'J4'!AB12+'J5'!AB12+'J6'!AB12+'J7'!AB12+'J8'!AB12+'J9'!AB12+'J10'!AB12++'J11'!AB12+'J12'!AB12+'J13'!AB12+'J14'!AB12+'J15'!AB12+'J16'!AB12+'J17'!AB12+'J18'!AB12+'J19'!AB12+'J20'!AB12+'J21'!AB12+'J22'!AB12 -> 3 | AE12: =IFERROR(AG12/SUM(AG12:AJ12), "") -> 0.58333333 | AF12: =SUM(AG12:AJ12) -> 24 | AG12: ='J1'!AE12+'J2'!AE12+'J3'!AE12+'J4'!AE12+'J5'!AE12+'J6'!AE12+'J7'!AE12+'J8'!AE12+'J9'!AE12+'J10'!AE12++'J11'!AE12+'J12'!AE12+'J13'!AE12+'J14'!AE12+'J15'!AE12+'J16'!AE12+'J17'!AE12+'J18'!AE12+'J19'!AE12+'J20'!AE12+'J21'!AE12+'J22'!AE12 -> 14 | AH12: ='J1'!AF12+'J2'!AF12+'J3'!AF12+'J4'!AF12+'J5'!AF12+'J6'!AF12+'J7'!AF12+'J8'!AF12+'J9'!AF12+'J10'!AF12++'J11'!AF12+'J12'!AF12+'J13'!AF12+'J14'!AF12+'J15'!AF12+'J16'!AF12+'J17'!AF12+'J18'!AF12+'J19'!AF12+'J20'!AF12+'J21'!AF12+'J22'!AF12 -> 8 | AI12: ='J1'!AG12+'J2'!AG12+'J3'!AG12+'J4'!AG12+'J5'!AG12+'J6'!AG12+'J7'!AG12+'J8'!AG12+'J9'!AG12+'J10'!AG12++'J11'!AG12+'J12'!AG12+'J13'!AG12+'J14'!AG12+'J15'!AG12+'J16'!AG12+'J17'!AG12+'J18'!AG12+'J19'!AG12+'J20'!AG12+'J21'!AG12+'J22'!AG12 -> 1 | AJ12: ='J1'!AH12+'J2'!AH12+'J3'!AH12+'J4'!AH12+'J5'!AH12+'J6'!AH12+'J7'!AH12+'J8'!AH12+'J9'!AH12+'J10'!AH12++'J11'!AH12+'J12'!AH12+'J13'!AH12+'J14'!AH12+'J15'!AH12+'J16'!AH12+'J17'!AH12+'J18'!AH12+'J19'!AH12+'J20'!AH12+'J21'!AH12+'J22'!AH12 -> 1 | AK12: =IFERROR(AM12/SUM(AM12:AP12), "") -> 1 | AL12: =SUM(AM12:AP12) -> 1 | AM12: ='J1'!AK12+'J2'!AK12+'J3'!AK12+'J4'!AK12+'J5'!AK12+'J6'!AK12+'J7'!AK12+'J8'!AK12+'J9'!AK12+'J10'!AK12++'J11'!AK12+'J12'!AK12+'J13'!AK12+'J14'!AK12+'J15'!AK12+'J16'!AK12+'J17'!AK12+'J18'!AK12+'J19'!AK12+'J20'!AK12+'J21'!AK12+'J22'!AK12 -> 1 | AN12: ='J1'!AL12+'J2'!AL12+'J3'!AL12+'J4'!AL12+'J5'!AL12+'J6'!AL12+'J7'!AL12+'J8'!AL12+'J9'!AL12+'J10'!AL12++'J11'!AL12+'J12'!AL12+'J13'!AL12+'J14'!AL12+'J15'!AL12+'J16'!AL12+'J17'!AL12+'J18'!AL12+'J19'!AL12+'J20'!AL12+'J21'!AL12+'J22'!AL12 -> 0 | AO12: ='J1'!AM12+'J2'!AM12+'J3'!AM12+'J4'!AM12+'J5'!AM12+'J6'!AM12+'J7'!AM12+'J8'!AM12+'J9'!AM12+'J10'!AM12++'J11'!AM12+'J12'!AM12+'J13'!AM12+'J14'!AM12+'J15'!AM12+'J16'!AM12+'J17'!AM12+'J18'!AM12+'J19'!AM12+'J20'!AM12+'J21'!AM12+'J22'!AM12 -> 0 | AP12: ='J1'!AN12+'J2'!AN12+'J3'!AN12+'J4'!AN12+'J5'!AN12+'J6'!AN12+'J7'!AN12+'J8'!AN12+'J9'!AN12+'J10'!AN12++'J11'!AN12+'J12'!AN12+'J13'!AN12+'J14'!AN12+'J15'!AN12+'J16'!AN12+'J17'!AN12+'J18'!AN12+'J19'!AN12+'J20'!AN12+'J21'!AN12+'J22'!AN12 -> 0 | AQ12: =SUM(AR12:AV12) -> 0 | AR12: ='J1'!AP12+'J2'!AP12+'J3'!AP12+'J4'!AP12+'J5'!AP12+'J6'!AP12+'J7'!AP12+'J8'!AP12+'J9'!AP12+'J10'!AP12++'J11'!AP12+'J12'!AP12+'J13'!AP12+'J14'!AP12+'J15'!AP12+'J16'!AP12+'J17'!AP12+'J18'!AP12+'J19'!AP12+'J20'!AP12+'J21'!AP12+'J22'!AP12 -> 0 | AS12: ='J1'!AQ12+'J2'!AQ12+'J3'!AQ12+'J4'!AQ12+'J5'!AQ12+'J6'!AQ12+'J7'!AQ12+'J8'!AQ12+'J9'!AQ12+'J10'!AQ12++'J11'!AQ12+'J12'!AQ12+'J13'!AQ12+'J14'!AQ12+'J15'!AQ12+'J16'!AQ12+'J17'!AQ12+'J18'!AQ12+'J19'!AQ12+'J20'!AQ12+'J21'!AQ12+'J22'!AQ12 -> 0 | AT12: ='J1'!AR12+'J2'!AR12+'J3'!AR12+'J4'!AR12+'J5'!AR12+'J6'!AR12+'J7'!AR12+'J8'!AR12+'J9'!AR12+'J10'!AR12++'J11'!AR12+'J12'!AR12+'J13'!AR12+'J14'!AR12+'J15'!AR12+'J16'!AR12+'J17'!AR12+'J18'!AR12+'J19'!AR12+'J20'!AR12+'J21'!AR12+'J22'!AR12 -> 0 | AU12: ='J1'!AS12+'J2'!AS12+'J3'!AS12+'J4'!AS12+'J5'!AS12+'J6'!AS12+'J7'!AS12+'J8'!AS12+'J9'!AS12+'J10'!AS12++'J11'!AS12+'J12'!AS12+'J13'!AS12+'J14'!AS12+'J15'!AS12+'J16'!AS12+'J17'!AS12+'J18'!AS12+'J19'!AS12+'J20'!AS12+'J21'!AS12+'J22'!AS12 -> 0 | AV12: ='J1'!AT12+'J2'!AT12+'J3'!AT12+'J4'!AT12+'J5'!AT12+'J6'!AT12+'J7'!AT12+'J8'!AT12+'J9'!AT12+'J10'!AT12++'J11'!AT12+'J12'!AT12+'J13'!AT12+'J14'!AT12+'J15'!AT12+'J16'!AT12+'J17'!AT12+'J18'!AT12+'J19'!AT12+'J20'!AT12+'J21'!AT12+'J22'!AT12 -> 0 | AW12: =AX12+AY12+AZ12+BA12+BB12+BC12+BD12+0.5*BE12+BF12+BG12+2*BH12+2*BI12 -> 6 | AX12: ='J1'!AV12+'J2'!AV12+'J3'!AV12+'J4'!AV12+'J5'!AV12+'J6'!AV12+'J7'!AV12+'J8'!AV12+'J9'!AV12+'J10'!AV12++'J11'!AV12+'J12'!AV12+'J13'!AV12+'J14'!AV12+'J15'!AV12+'J16'!AV12+'J17'!AV12+'J18'!AV12+'J19'!AV12+'J20'!AV12+'J21'!AV12+'J22'!AV12 -> 3 | AY12: ='J1'!AW12+'J2'!AW12+'J3'!AW12+'J4'!AW12+'J5'!AW12+'J6'!AW12+'J7'!AW12+'J8'!AW12+'J9'!AW12+'J10'!AW12++'J11'!AW12+'J12'!AW12+'J13'!AW12+'J14'!AW12+'J15'!AW12+'J16'!AW12+'J17'!AW12+'J18'!AW12+'J19'!AW12+'J20'!AW12+'J21'!AW12+'J22'!AW12 -> 1 | AZ12: ='J1'!AX12+'J2'!AX12+'J3'!AX12+'J4'!AX12+'J5'!AX12+'J6'!AX12+'J7'!AX12+'J8'!AX12+'J9'!AX12+'J10'!AX12++'J11'!AX12+'J12'!AX12+'J13'!AX12+'J14'!AX12+'J15'!AX12+'J16'!AX12+'J17'!AX12+'J18'!AX12+'J19'!AX12+'J20'!AX12+'J21'!AX12+'J22'!AX12 -> 1 | BA12: ='J1'!AY12+'J2'!AY12+'J3'!AY12+'J4'!AY12+'J5'!AY12+'J6'!AY12+'J7'!AY12+'J8'!AY12+'J9'!AY12+'J10'!AY12++'J11'!AY12+'J12'!AY12+'J13'!AY12+'J14'!AY12+'J15'!AY12+'J16'!AY12+'J17'!AY12+'J18'!AY12+'J19'!AY12+'J20'!AY12+'J21'!AY12+'J22'!AY12 -> 0 | BB12: ='J1'!AZ12+'J2'!AZ12+'J3'!AZ12+'J4'!AZ12+'J5'!AZ12+'J6'!AZ12+'J7'!AZ12+'J8'!AZ12+'J9'!AZ12+'J10'!AZ12++'J11'!AZ12+'J12'!AZ12+'J13'!AZ12+'J14'!AZ12+'J15'!AZ12+'J16'!AZ12+'J17'!AZ12+'J18'!AZ12+'J19'!AZ12+'J20'!AZ12+'J21'!AZ12+'J22'!AZ12 -> 0 | BC12: ='J1'!BA12+'J2'!BA12+'J3'!BA12+'J4'!BA12+'J5'!BA12+'J6'!BA12+'J7'!BA12+'J8'!BA12+'J9'!BA12+'J10'!BA12++'J11'!BA12+'J12'!BA12+'J13'!BA12+'J14'!BA12+'J15'!BA12+'J16'!BA12+'J17'!BA12+'J18'!BA12+'J19'!BA12+'J20'!BA12+'J21'!BA12+'J22'!BA12 -> 0 | BD12: ='J1'!BB12+'J2'!BB12+'J3'!BB12+'J4'!BB12+'J5'!BB12+'J6'!BB12+'J7'!BB12+'J8'!BB12+'J9'!BB12+'J10'!BB12++'J11'!BB12+'J12'!BB12+'J13'!BB12+'J14'!BB12+'J15'!BB12+'J16'!BB12+'J17'!BB12+'J18'!BB12+'J19'!BB12+'J20'!BB12+'J21'!BB12+'J22'!BB12 -> 0 | BE12: ='J1'!BC12+'J2'!BC12+'J3'!BC12+'J4'!BC12+'J5'!BC12+'J6'!BC12+'J7'!BC12+'J8'!BC12+'J9'!BC12+'J10'!BC12++'J11'!BC12+'J12'!BC12+'J13'!BC12+'J14'!BC12+'J15'!BC12+'J16'!BC12+'J17'!BC12+'J18'!BC12+'J19'!BC12+'J20'!BC12+'J21'!BC12+'J22'!BC12 -> 0 | ... BI12: ='J1'!BG12+'J2'!BG12+'J3'!BG12+'J4'!BG12+'J5'!BG12+'J6'!BG12+'J7'!BG12+'J8'!BG12+'J9'!BG12+'J10'!BG12++'J11'!BG12+'J12'!BG12+'J13'!BG12+'J14'!BG12+'J15'!BG12+'J16'!BG12+'J17'!BG12+'J18'!BG12+'J19'!BG12+'J20'!BG12+'J21'!BG12+'J22'!BG12 -> 0
F13: IKER | H13: 9 | I13: 0 | J13: =('J1'!I13+'J2'!I13+'J3'!I13+'J4'!I12+'J5'!I13+'J6'!I13+'J7'!I13+'J8'!I13+'J9'!I13+'J10'!I13++'J11'!I13+'J12'!I13+'J13'!I13+'J14'!I13+'J15'!I13+'J16'!I13+'J17'!I13+'J18'!I13+'J19'!I13+'J20'!I13+'J21'!I13+'J22'!I13)/H13 -> 22.666667 | K13: =J13/60 -> 0.37777778 | L13: =('J1'!J13+'J2'!J13+'J3'!J13+'J4'!J13+'J5'!J13+'J6'!J13+'J7'!J13+'J8'!J13+'J9'!J13+'J10'!J13++'J11'!J13+'J12'!J13+'J13'!J13+'J14'!J13+'J15'!J13+'J16'!J13+'J17'!J13+'J18'!J13+'J19'!J13+'J20'!J13+'J21'!J13+'J22'!J13)/$C$3 -> 0 | M13: =('J1'!K13+'J2'!K13+'J3'!K13+'J4'!K13+'J5'!K13+'J6'!K13+'J7'!K13+'J8'!K13+'J9'!K13+'J10'!K13++'J11'!K13+'J12'!K13+'J13'!K13+'J14'!K13+'J15'!K13+'J16'!K13+'J17'!K13+'J18'!K13+'J19'!K13+'J20'!K13+'J21'!K13+'J22'!K13)/$C$3 -> 0 | N13: =('J1'!L13+'J2'!L13+'J3'!L13+'J4'!L13+'J5'!L13+'J6'!L13+'J7'!L13+'J8'!L13+'J9'!L13+'J10'!L13+'J11'!L13+'J12'!L13+'J13'!L13+'J14'!L13+'J15'!L13+'J16'!L13+'J17'!L13+'J18'!L13+'J19'!L13+'J20'!L13+'J21'!L13+'J22'!L13)/$C$3 -> 0.055555556 | O13: =IFERROR(Q13/P13,"") -> 0.61538462 | P13: =SUM(T13:X13)+SUM(AG13:AJ13)+SUM(AM13:AP13)+SUM(AA13:AD13) -> 13 | Q13: =T13+AG13+AM13+AA13 -> 8 | R13: =IF(SUM(T13:X13)=0,"",T13/SUM(T13:X13)) -> 0.33333333 | S13: =SUM(T13:X13) -> 3 | T13: ='J1'!R13+'J2'!R13+'J3'!R13+'J4'!R13+'J5'!R13+'J6'!R13+'J7'!R13+'J8'!R13+'J9'!R13+'J10'!R13++'J11'!R13+'J12'!R13+'J13'!R13+'J14'!R13+'J15'!R13+'J16'!R13+'J17'!R13+'J18'!R13+'J19'!R13+'J20'!R13+'J21'!R13+'J22'!R13 -> 1 | U13: ='J1'!S13+'J2'!S13+'J3'!S13+'J4'!S13+'J5'!S13+'J6'!S13+'J7'!S13+'J8'!S13+'J9'!S13+'J10'!S13++'J11'!S13+'J12'!S13+'J13'!S13+'J14'!S13+'J15'!S13+'J16'!S13+'J17'!S13+'J18'!S13+'J19'!S13+'J20'!S13+'J21'!S13+'J22'!S13 -> 1 | V13: ='J1'!T13+'J2'!T13+'J3'!T13+'J4'!T13+'J5'!T13+'J6'!T13+'J7'!T13+'J8'!T13+'J9'!T13+'J10'!T13++'J11'!T13+'J12'!T13+'J13'!T13+'J14'!T13+'J15'!T13+'J16'!T13+'J17'!T13+'J18'!T13+'J19'!T13+'J20'!T13+'J21'!T13+'J22'!T13 -> 0 | W13: ='J1'!U13+'J2'!U13+'J3'!U13+'J4'!U13+'J5'!U13+'J6'!U13+'J7'!U13+'J8'!U13+'J9'!U13+'J10'!U13++'J11'!U13+'J12'!U13+'J13'!U13+'J14'!U13+'J15'!U13+'J16'!U13+'J17'!U13+'J18'!U13+'J19'!U13+'J20'!U13+'J21'!U13+'J22'!U13 -> 1 | X13: ='J1'!V13+'J2'!V13+'J3'!V13+'J4'!V13+'J5'!V13+'J6'!V13+'J7'!V13+'J8'!V13+'J9'!V13+'J10'!V13++'J11'!V13+'J12'!V13+'J13'!V13+'J14'!V13+'J15'!V13+'J16'!V13+'J17'!V13+'J18'!V13+'J19'!V13+'J20'!V13+'J21'!V13+'J22'!V13 -> 0 | Y13: =IFERROR(AA13/SUM(AA13:AD13), "") | Z13: =SUM(AA13:AD13) -> 0 | AA13: ='J1'!Y13+'J2'!Y13+'J3'!Y13+'J4'!Y13+'J5'!Y13+'J6'!Y13+'J7'!Y13+'J8'!Y13+'J9'!Y13+'J10'!Y13++'J11'!Y13+'J12'!Y13+'J13'!Y13+'J14'!Y13+'J15'!Y13+'J16'!Y13+'J17'!Y13+'J18'!Y13+'J19'!Y13+'J20'!Y13+'J21'!Y13+'J22'!Y13 -> 0 | AB13: ='J1'!Z13+'J2'!Z13+'J3'!Z13+'J4'!Z13+'J5'!Z13+'J6'!Z13+'J7'!Z13+'J8'!Z13+'J9'!Z13+'J10'!Z13++'J11'!Z13+'J12'!Z13+'J13'!Z13+'J14'!Z13+'J15'!Z13+'J16'!Z13+'J17'!Z13+'J18'!Z13+'J19'!Z13+'J20'!Z13+'J21'!Z13+'J22'!Z13 -> 0 | AC13: ='J1'!AA13+'J2'!AA13+'J3'!AA13+'J4'!AA13+'J5'!AA13+'J6'!AA13+'J7'!AA13+'J8'!AA13+'J9'!AA13+'J10'!AA13++'J11'!AA13+'J12'!AA13+'J13'!AA13+'J14'!AA13+'J15'!AA13+'J16'!AA13+'J17'!AA13+'J18'!AA13+'J19'!AA13+'J20'!AA13+'J21'!AA13+'J22'!AA13 -> 0 | AD13: ='J1'!AB13+'J2'!AB13+'J3'!AB13+'J4'!AB13+'J5'!AB13+'J6'!AB13+'J7'!AB13+'J8'!AB13+'J9'!AB13+'J10'!AB13++'J11'!AB13+'J12'!AB13+'J13'!AB13+'J14'!AB13+'J15'!AB13+'J16'!AB13+'J17'!AB13+'J18'!AB13+'J19'!AB13+'J20'!AB13+'J21'!AB13+'J22'!AB13 -> 0 | AE13: =IFERROR(AG13/SUM(AG13:AJ13), "") -> 0.7 | AF13: =SUM(AG13:AJ13) -> 10 | AG13: ='J1'!AE13+'J2'!AE13+'J3'!AE13+'J4'!AE13+'J5'!AE13+'J6'!AE13+'J7'!AE13+'J8'!AE13+'J9'!AE13+'J10'!AE13++'J11'!AE13+'J12'!AE13+'J13'!AE13+'J14'!AE13+'J15'!AE13+'J16'!AE13+'J17'!AE13+'J18'!AE13+'J19'!AE13+'J20'!AE13+'J21'!AE13+'J22'!AE13 -> 7 | AH13: ='J1'!AF13+'J2'!AF13+'J3'!AF13+'J4'!AF13+'J5'!AF13+'J6'!AF13+'J7'!AF13+'J8'!AF13+'J9'!AF13+'J10'!AF13++'J11'!AF13+'J12'!AF13+'J13'!AF13+'J14'!AF13+'J15'!AF13+'J16'!AF13+'J17'!AF13+'J18'!AF13+'J19'!AF13+'J20'!AF13+'J21'!AF13+'J22'!AF13 -> 0 | AI13: ='J1'!AG13+'J2'!AG13+'J3'!AG13+'J4'!AG13+'J5'!AG13+'J6'!AG13+'J7'!AG13+'J8'!AG13+'J9'!AG13+'J10'!AG13++'J11'!AG13+'J12'!AG13+'J13'!AG13+'J14'!AG13+'J15'!AG13+'J16'!AG13+'J17'!AG13+'J18'!AG13+'J19'!AG13+'J20'!AG13+'J21'!AG13+'J22'!AG13 -> 0 | AJ13: ='J1'!AH13+'J2'!AH13+'J3'!AH13+'J4'!AH13+'J5'!AH13+'J6'!AH13+'J7'!AH13+'J8'!AH13+'J9'!AH13+'J10'!AH13++'J11'!AH13+'J12'!AH13+'J13'!AH13+'J14'!AH13+'J15'!AH13+'J16'!AH13+'J17'!AH13+'J18'!AH13+'J19'!AH13+'J20'!AH13+'J21'!AH13+'J22'!AH13 -> 3 | AK13: =IFERROR(AM13/SUM(AM13:AP13), "") | AL13: =SUM(AM13:AP13) -> 0 | AM13: ='J1'!AK13+'J2'!AK13+'J3'!AK13+'J4'!AK13+'J5'!AK13+'J6'!AK13+'J7'!AK13+'J8'!AK13+'J9'!AK13+'J10'!AK13++'J11'!AK13+'J12'!AK13+'J13'!AK13+'J14'!AK13+'J15'!AK13+'J16'!AK13+'J17'!AK13+'J18'!AK13+'J19'!AK13+'J20'!AK13+'J21'!AK13+'J22'!AK13 -> 0 | AN13: ='J1'!AL13+'J2'!AL13+'J3'!AL13+'J4'!AL13+'J5'!AL13+'J6'!AL13+'J7'!AL13+'J8'!AL13+'J9'!AL13+'J10'!AL13++'J11'!AL13+'J12'!AL13+'J13'!AL13+'J14'!AL13+'J15'!AL13+'J16'!AL13+'J17'!AL13+'J18'!AL13+'J19'!AL13+'J20'!AL13+'J21'!AL13+'J22'!AL13 -> 0 | AO13: ='J1'!AM13+'J2'!AM13+'J3'!AM13+'J4'!AM13+'J5'!AM13+'J6'!AM13+'J7'!AM13+'J8'!AM13+'J9'!AM13+'J10'!AM13++'J11'!AM13+'J12'!AM13+'J13'!AM13+'J14'!AM13+'J15'!AM13+'J16'!AM13+'J17'!AM13+'J18'!AM13+'J19'!AM13+'J20'!AM13+'J21'!AM13+'J22'!AM13 -> 0 | AP13: ='J1'!AN13+'J2'!AN13+'J3'!AN13+'J4'!AN13+'J5'!AN13+'J6'!AN13+'J7'!AN13+'J8'!AN13+'J9'!AN13+'J10'!AN13++'J11'!AN13+'J12'!AN13+'J13'!AN13+'J14'!AN13+'J15'!AN13+'J16'!AN13+'J17'!AN13+'J18'!AN13+'J19'!AN13+'J20'!AN13+'J21'!AN13+'J22'!AN13 -> 0 | AQ13: =SUM(AR13:AV13) -> 4 | AR13: ='J1'!AP13+'J2'!AP13+'J3'!AP13+'J4'!AP13+'J5'!AP13+'J6'!AP13+'J7'!AP13+'J8'!AP13+'J9'!AP13+'J10'!AP13++'J11'!AP13+'J12'!AP13+'J13'!AP13+'J14'!AP13+'J15'!AP13+'J16'!AP13+'J17'!AP13+'J18'!AP13+'J19'!AP13+'J20'!AP13+'J21'!AP13+'J22'!AP13 -> 0 | AS13: ='J1'!AQ13+'J2'!AQ13+'J3'!AQ13+'J4'!AQ13+'J5'!AQ13+'J6'!AQ13+'J7'!AQ13+'J8'!AQ13+'J9'!AQ13+'J10'!AQ13++'J11'!AQ13+'J12'!AQ13+'J13'!AQ13+'J14'!AQ13+'J15'!AQ13+'J16'!AQ13+'J17'!AQ13+'J18'!AQ13+'J19'!AQ13+'J20'!AQ13+'J21'!AQ13+'J22'!AQ13 -> 0 | AT13: ='J1'!AR13+'J2'!AR13+'J3'!AR13+'J4'!AR13+'J5'!AR13+'J6'!AR13+'J7'!AR13+'J8'!AR13+'J9'!AR13+'J10'!AR13++'J11'!AR13+'J12'!AR13+'J13'!AR13+'J14'!AR13+'J15'!AR13+'J16'!AR13+'J17'!AR13+'J18'!AR13+'J19'!AR13+'J20'!AR13+'J21'!AR13+'J22'!AR13 -> 4 | AU13: ='J1'!AS13+'J2'!AS13+'J3'!AS13+'J4'!AS13+'J5'!AS13+'J6'!AS13+'J7'!AS13+'J8'!AS13+'J9'!AS13+'J10'!AS13++'J11'!AS13+'J12'!AS13+'J13'!AS13+'J14'!AS13+'J15'!AS13+'J16'!AS13+'J17'!AS13+'J18'!AS13+'J19'!AS13+'J20'!AS13+'J21'!AS13+'J22'!AS13 -> 0 | AV13: ='J1'!AT13+'J2'!AT13+'J3'!AT13+'J4'!AT13+'J5'!AT13+'J6'!AT13+'J7'!AT13+'J8'!AT13+'J9'!AT13+'J10'!AT13++'J11'!AT13+'J12'!AT13+'J13'!AT13+'J14'!AT13+'J15'!AT13+'J16'!AT13+'J17'!AT13+'J18'!AT13+'J19'!AT13+'J20'!AT13+'J21'!AT13+'J22'!AT13 -> 0 | AW13: =AX13+AY13+AZ13+BA13+BB13+BC13+BD13+0.5*BE13+BF13+BG13+2*BH13+2*BI13 -> 3 | AX13: ='J1'!AV13+'J2'!AV13+'J3'!AV13+'J4'!AV13+'J5'!AV13+'J6'!AV13+'J7'!AV13+'J8'!AV13+'J9'!AV13+'J10'!AV13++'J11'!AV13+'J12'!AV13+'J13'!AV13+'J14'!AV13+'J15'!AV13+'J16'!AV13+'J17'!AV13+'J18'!AV13+'J19'!AV13+'J20'!AV13+'J21'!AV13+'J22'!AV13 -> 1 | AY13: ='J1'!AW13+'J2'!AW13+'J3'!AW13+'J4'!AW13+'J5'!AW13+'J6'!AW13+'J7'!AW13+'J8'!AW13+'J9'!AW13+'J10'!AW13++'J11'!AW13+'J12'!AW13+'J13'!AW13+'J14'!AW13+'J15'!AW13+'J16'!AW13+'J17'!AW13+'J18'!AW13+'J19'!AW13+'J20'!AW13+'J21'!AW13+'J22'!AW13 -> 0 | AZ13: ='J1'!AX13+'J2'!AX13+'J3'!AX13+'J4'!AX13+'J5'!AX13+'J6'!AX13+'J7'!AX13+'J8'!AX13+'J9'!AX13+'J10'!AX13++'J11'!AX13+'J12'!AX13+'J13'!AX13+'J14'!AX13+'J15'!AX13+'J16'!AX13+'J17'!AX13+'J18'!AX13+'J19'!AX13+'J20'!AX13+'J21'!AX13+'J22'!AX13 -> 1 | BA13: ='J1'!AY13+'J2'!AY13+'J3'!AY13+'J4'!AY13+'J5'!AY13+'J6'!AY13+'J7'!AY13+'J8'!AY13+'J9'!AY13+'J10'!AY13++'J11'!AY13+'J12'!AY13+'J13'!AY13+'J14'!AY13+'J15'!AY13+'J16'!AY13+'J17'!AY13+'J18'!AY13+'J19'!AY13+'J20'!AY13+'J21'!AY13+'J22'!AY13 -> 0 | BB13: ='J1'!AZ13+'J2'!AZ13+'J3'!AZ13+'J4'!AZ13+'J5'!AZ13+'J6'!AZ13+'J7'!AZ13+'J8'!AZ13+'J9'!AZ13+'J10'!AZ13++'J11'!AZ13+'J12'!AZ13+'J13'!AZ13+'J14'!AZ13+'J15'!AZ13+'J16'!AZ13+'J17'!AZ13+'J18'!AZ13+'J19'!AZ13+'J20'!AZ13+'J21'!AZ13+'J22'!AZ13 -> 0 | BC13: ='J1'!BA13+'J2'!BA13+'J3'!BA13+'J4'!BA13+'J5'!BA13+'J6'!BA13+'J7'!BA13+'J8'!BA13+'J9'!BA13+'J10'!BA13++'J11'!BA13+'J12'!BA13+'J13'!BA13+'J14'!BA13+'J15'!BA13+'J16'!BA13+'J17'!BA13+'J18'!BA13+'J19'!BA13+'J20'!BA13+'J21'!BA13+'J22'!BA13 -> 1 | BD13: ='J1'!BB13+'J2'!BB13+'J3'!BB13+'J4'!BB13+'J5'!BB13+'J6'!BB13+'J7'!BB13+'J8'!BB13+'J9'!BB13+'J10'!BB13++'J11'!BB13+'J12'!BB13+'J13'!BB13+'J14'!BB13+'J15'!BB13+'J16'!BB13+'J17'!BB13+'J18'!BB13+'J19'!BB13+'J20'!BB13+'J21'!BB13+'J22'!BB13 -> 0 | BE13: ='J1'!BC13+'J2'!BC13+'J3'!BC13+'J4'!BC13+'J5'!BC13+'J6'!BC13+'J7'!BC13+'J8'!BC13+'J9'!BC13+'J10'!BC13++'J11'!BC13+'J12'!BC13+'J13'!BC13+'J14'!BC13+'J15'!BC13+'J16'!BC13+'J17'!BC13+'J18'!BC13+'J19'!BC13+'J20'!BC13+'J21'!BC13+'J22'!BC13 -> 0 | ... BI13: ='J1'!BG13+'J2'!BG13+'J3'!BG13+'J4'!BG13+'J5'!BG13+'J6'!BG13+'J7'!BG13+'J8'!BG13+'J9'!BG13+'J10'!BG13++'J11'!BG13+'J12'!BG13+'J13'!BG13+'J14'!BG13+'J15'!BG13+'J16'!BG13+'J17'!BG13+'J18'!BG13+'J19'!BG13+'J20'!BG13+'J21'!BG13+'J22'!BG13 -> 0
F14: IÑIGO | H14: 9 | I14: 0 | J14: =('J1'!I14+'J2'!I14+'J3'!I14+'J4'!I13+'J5'!I14+'J6'!I14+'J7'!I14+'J8'!I14+'J9'!I14+'J10'!I14++'J11'!I14+'J12'!I14+'J13'!I14+'J14'!I14+'J15'!I14+'J16'!I14+'J17'!I14+'J18'!I14+'J19'!I14+'J20'!I14+'J21'!I14+'J22'!I14)/H14 -> 25.666667 | K14: =J14/60 -> 0.42777778 | L14: =('J1'!J14+'J2'!J14+'J3'!J14+'J4'!J14+'J5'!J14+'J6'!J14+'J7'!J14+'J8'!J14+'J9'!J14+'J10'!J14++'J11'!J14+'J12'!J14+'J13'!J14+'J14'!J14+'J15'!J14+'J16'!J14+'J17'!J14+'J18'!J14+'J19'!J14+'J20'!J14+'J21'!J14+'J22'!J14)/$C$3 -> 0 | M14: =('J1'!K14+'J2'!K14+'J3'!K14+'J4'!K14+'J5'!K14+'J6'!K14+'J7'!K14+'J8'!K14+'J9'!K14+'J10'!K14++'J11'!K14+'J12'!K14+'J13'!K14+'J14'!K14+'J15'!K14+'J16'!K14+'J17'!K14+'J18'!K14+'J19'!K14+'J20'!K14+'J21'!K14+'J22'!K14)/$C$3 -> 0 | N14: =('J1'!L14+'J2'!L14+'J3'!L14+'J4'!L14+'J5'!L14+'J6'!L14+'J7'!L14+'J8'!L14+'J9'!L14+'J10'!L14+'J11'!L14+'J12'!L14+'J13'!L14+'J14'!L14+'J15'!L14+'J16'!L14+'J17'!L14+'J18'!L14+'J19'!L14+'J20'!L14+'J21'!L14+'J22'!L14)/$C$3 -> -0.11111111 | O14: =IFERROR(Q14/P14,"") -> 0.63333333 | P14: =SUM(T14:X14)+SUM(AG14:AJ14)+SUM(AM14:AP14)+SUM(AA14:AD14) -> 60 | Q14: =T14+AG14+AM14+AA14 -> 38 | R14: =IF(SUM(T14:X14)=0,"",T14/SUM(T14:X14)) -> 0.22222222 | S14: =SUM(T14:X14) -> 18 | T14: ='J1'!R14+'J2'!R14+'J3'!R14+'J4'!R14+'J5'!R14+'J6'!R14+'J7'!R14+'J8'!R14+'J9'!R14+'J10'!R14++'J11'!R14+'J12'!R14+'J13'!R14+'J14'!R14+'J15'!R14+'J16'!R14+'J17'!R14+'J18'!R14+'J19'!R14+'J20'!R14+'J21'!R14+'J22'!R14 -> 4 | U14: ='J1'!S14+'J2'!S14+'J3'!S14+'J4'!S14+'J5'!S14+'J6'!S14+'J7'!S14+'J8'!S14+'J9'!S14+'J10'!S14++'J11'!S14+'J12'!S14+'J13'!S14+'J14'!S14+'J15'!S14+'J16'!S14+'J17'!S14+'J18'!S14+'J19'!S14+'J20'!S14+'J21'!S14+'J22'!S14 -> 8 | V14: ='J1'!T14+'J2'!T14+'J3'!T14+'J4'!T14+'J5'!T14+'J6'!T14+'J7'!T14+'J8'!T14+'J9'!T14+'J10'!T14++'J11'!T14+'J12'!T14+'J13'!T14+'J14'!T14+'J15'!T14+'J16'!T14+'J17'!T14+'J18'!T14+'J19'!T14+'J20'!T14+'J21'!T14+'J22'!T14 -> 0 | W14: ='J1'!U14+'J2'!U14+'J3'!U14+'J4'!U14+'J5'!U14+'J6'!U14+'J7'!U14+'J8'!U14+'J9'!U14+'J10'!U14++'J11'!U14+'J12'!U14+'J13'!U14+'J14'!U14+'J15'!U14+'J16'!U14+'J17'!U14+'J18'!U14+'J19'!U14+'J20'!U14+'J21'!U14+'J22'!U14 -> 6 | X14: ='J1'!V14+'J2'!V14+'J3'!V14+'J4'!V14+'J5'!V14+'J6'!V14+'J7'!V14+'J8'!V14+'J9'!V14+'J10'!V14++'J11'!V14+'J12'!V14+'J13'!V14+'J14'!V14+'J15'!V14+'J16'!V14+'J17'!V14+'J18'!V14+'J19'!V14+'J20'!V14+'J21'!V14+'J22'!V14 -> 0 | Y14: =IFERROR(AA14/SUM(AA14:AD14), "") -> 0.5 | Z14: =SUM(AA14:AD14) -> 2 | AA14: ='J1'!Y14+'J2'!Y14+'J3'!Y14+'J4'!Y14+'J5'!Y14+'J6'!Y14+'J7'!Y14+'J8'!Y14+'J9'!Y14+'J10'!Y14++'J11'!Y14+'J12'!Y14+'J13'!Y14+'J14'!Y14+'J15'!Y14+'J16'!Y14+'J17'!Y14+'J18'!Y14+'J19'!Y14+'J20'!Y14+'J21'!Y14+'J22'!Y14 -> 1 | AB14: ='J1'!Z14+'J2'!Z14+'J3'!Z14+'J4'!Z14+'J5'!Z14+'J6'!Z14+'J7'!Z14+'J8'!Z14+'J9'!Z14+'J10'!Z14++'J11'!Z14+'J12'!Z14+'J13'!Z14+'J14'!Z14+'J15'!Z14+'J16'!Z14+'J17'!Z14+'J18'!Z14+'J19'!Z14+'J20'!Z14+'J21'!Z14+'J22'!Z14 -> 1 | AC14: ='J1'!AA14+'J2'!AA14+'J3'!AA14+'J4'!AA14+'J5'!AA14+'J6'!AA14+'J7'!AA14+'J8'!AA14+'J9'!AA14+'J10'!AA14++'J11'!AA14+'J12'!AA14+'J13'!AA14+'J14'!AA14+'J15'!AA14+'J16'!AA14+'J17'!AA14+'J18'!AA14+'J19'!AA14+'J20'!AA14+'J21'!AA14+'J22'!AA14 -> 0 | AD14: ='J1'!AB14+'J2'!AB14+'J3'!AB14+'J4'!AB14+'J5'!AB14+'J6'!AB14+'J7'!AB14+'J8'!AB14+'J9'!AB14+'J10'!AB14++'J11'!AB14+'J12'!AB14+'J13'!AB14+'J14'!AB14+'J15'!AB14+'J16'!AB14+'J17'!AB14+'J18'!AB14+'J19'!AB14+'J20'!AB14+'J21'!AB14+'J22'!AB14 -> 0 | AE14: =IFERROR(AG14/SUM(AG14:AJ14), "") -> 0.83783784 | AF14: =SUM(AG14:AJ14) -> 37 | AG14: ='J1'!AE14+'J2'!AE14+'J3'!AE14+'J4'!AE14+'J5'!AE14+'J6'!AE14+'J7'!AE14+'J8'!AE14+'J9'!AE14+'J10'!AE14++'J11'!AE14+'J12'!AE14+'J13'!AE14+'J14'!AE14+'J15'!AE14+'J16'!AE14+'J17'!AE14+'J18'!AE14+'J19'!AE14+'J20'!AE14+'J21'!AE14+'J22'!AE14 -> 31 | AH14: ='J1'!AF14+'J2'!AF14+'J3'!AF14+'J4'!AF14+'J5'!AF14+'J6'!AF14+'J7'!AF14+'J8'!AF14+'J9'!AF14+'J10'!AF14++'J11'!AF14+'J12'!AF14+'J13'!AF14+'J14'!AF14+'J15'!AF14+'J16'!AF14+'J17'!AF14+'J18'!AF14+'J19'!AF14+'J20'!AF14+'J21'!AF14+'J22'!AF14 -> 4 | AI14: ='J1'!AG14+'J2'!AG14+'J3'!AG14+'J4'!AG14+'J5'!AG14+'J6'!AG14+'J7'!AG14+'J8'!AG14+'J9'!AG14+'J10'!AG14++'J11'!AG14+'J12'!AG14+'J13'!AG14+'J14'!AG14+'J15'!AG14+'J16'!AG14+'J17'!AG14+'J18'!AG14+'J19'!AG14+'J20'!AG14+'J21'!AG14+'J22'!AG14 -> 0 | AJ14: ='J1'!AH14+'J2'!AH14+'J3'!AH14+'J4'!AH14+'J5'!AH14+'J6'!AH14+'J7'!AH14+'J8'!AH14+'J9'!AH14+'J10'!AH14++'J11'!AH14+'J12'!AH14+'J13'!AH14+'J14'!AH14+'J15'!AH14+'J16'!AH14+'J17'!AH14+'J18'!AH14+'J19'!AH14+'J20'!AH14+'J21'!AH14+'J22'!AH14 -> 2 | AK14: =IFERROR(AM14/SUM(AM14:AP14), "") -> 0.66666667 | AL14: =SUM(AM14:AP14) -> 3 | AM14: ='J1'!AK14+'J2'!AK14+'J3'!AK14+'J4'!AK14+'J5'!AK14+'J6'!AK14+'J7'!AK14+'J8'!AK14+'J9'!AK14+'J10'!AK14++'J11'!AK14+'J12'!AK14+'J13'!AK14+'J14'!AK14+'J15'!AK14+'J16'!AK14+'J17'!AK14+'J18'!AK14+'J19'!AK14+'J20'!AK14+'J21'!AK14+'J22'!AK14 -> 2 | AN14: ='J1'!AL14+'J2'!AL14+'J3'!AL14+'J4'!AL14+'J5'!AL14+'J6'!AL14+'J7'!AL14+'J8'!AL14+'J9'!AL14+'J10'!AL14++'J11'!AL14+'J12'!AL14+'J13'!AL14+'J14'!AL14+'J15'!AL14+'J16'!AL14+'J17'!AL14+'J18'!AL14+'J19'!AL14+'J20'!AL14+'J21'!AL14+'J22'!AL14 -> 1 | AO14: ='J1'!AM14+'J2'!AM14+'J3'!AM14+'J4'!AM14+'J5'!AM14+'J6'!AM14+'J7'!AM14+'J8'!AM14+'J9'!AM14+'J10'!AM14++'J11'!AM14+'J12'!AM14+'J13'!AM14+'J14'!AM14+'J15'!AM14+'J16'!AM14+'J17'!AM14+'J18'!AM14+'J19'!AM14+'J20'!AM14+'J21'!AM14+'J22'!AM14 -> 0 | AP14: ='J1'!AN14+'J2'!AN14+'J3'!AN14+'J4'!AN14+'J5'!AN14+'J6'!AN14+'J7'!AN14+'J8'!AN14+'J9'!AN14+'J10'!AN14++'J11'!AN14+'J12'!AN14+'J13'!AN14+'J14'!AN14+'J15'!AN14+'J16'!AN14+'J17'!AN14+'J18'!AN14+'J19'!AN14+'J20'!AN14+'J21'!AN14+'J22'!AN14 -> 0 | AQ14: =SUM(AR14:AV14) -> 6 | AR14: ='J1'!AP14+'J2'!AP14+'J3'!AP14+'J4'!AP14+'J5'!AP14+'J6'!AP14+'J7'!AP14+'J8'!AP14+'J9'!AP14+'J10'!AP14++'J11'!AP14+'J12'!AP14+'J13'!AP14+'J14'!AP14+'J15'!AP14+'J16'!AP14+'J17'!AP14+'J18'!AP14+'J19'!AP14+'J20'!AP14+'J21'!AP14+'J22'!AP14 -> 0 | AS14: ='J1'!AQ14+'J2'!AQ14+'J3'!AQ14+'J4'!AQ14+'J5'!AQ14+'J6'!AQ14+'J7'!AQ14+'J8'!AQ14+'J9'!AQ14+'J10'!AQ14++'J11'!AQ14+'J12'!AQ14+'J13'!AQ14+'J14'!AQ14+'J15'!AQ14+'J16'!AQ14+'J17'!AQ14+'J18'!AQ14+'J19'!AQ14+'J20'!AQ14+'J21'!AQ14+'J22'!AQ14 -> 1 | AT14: ='J1'!AR14+'J2'!AR14+'J3'!AR14+'J4'!AR14+'J5'!AR14+'J6'!AR14+'J7'!AR14+'J8'!AR14+'J9'!AR14+'J10'!AR14++'J11'!AR14+'J12'!AR14+'J13'!AR14+'J14'!AR14+'J15'!AR14+'J16'!AR14+'J17'!AR14+'J18'!AR14+'J19'!AR14+'J20'!AR14+'J21'!AR14+'J22'!AR14 -> 5 | AU14: ='J1'!AS14+'J2'!AS14+'J3'!AS14+'J4'!AS14+'J5'!AS14+'J6'!AS14+'J7'!AS14+'J8'!AS14+'J9'!AS14+'J10'!AS14++'J11'!AS14+'J12'!AS14+'J13'!AS14+'J14'!AS14+'J15'!AS14+'J16'!AS14+'J17'!AS14+'J18'!AS14+'J19'!AS14+'J20'!AS14+'J21'!AS14+'J22'!AS14 -> 0 | AV14: ='J1'!AT14+'J2'!AT14+'J3'!AT14+'J4'!AT14+'J5'!AT14+'J6'!AT14+'J7'!AT14+'J8'!AT14+'J9'!AT14+'J10'!AT14++'J11'!AT14+'J12'!AT14+'J13'!AT14+'J14'!AT14+'J15'!AT14+'J16'!AT14+'J17'!AT14+'J18'!AT14+'J19'!AT14+'J20'!AT14+'J21'!AT14+'J22'!AT14 -> 0 | AW14: =AX14+AY14+AZ14+BA14+BB14+BC14+BD14+0.5*BE14+BF14+BG14+2*BH14+2*BI14 -> 13 | AX14: ='J1'!AV14+'J2'!AV14+'J3'!AV14+'J4'!AV14+'J5'!AV14+'J6'!AV14+'J7'!AV14+'J8'!AV14+'J9'!AV14+'J10'!AV14++'J11'!AV14+'J12'!AV14+'J13'!AV14+'J14'!AV14+'J15'!AV14+'J16'!AV14+'J17'!AV14+'J18'!AV14+'J19'!AV14+'J20'!AV14+'J21'!AV14+'J22'!AV14 -> 9 | AY14: ='J1'!AW14+'J2'!AW14+'J3'!AW14+'J4'!AW14+'J5'!AW14+'J6'!AW14+'J7'!AW14+'J8'!AW14+'J9'!AW14+'J10'!AW14++'J11'!AW14+'J12'!AW14+'J13'!AW14+'J14'!AW14+'J15'!AW14+'J16'!AW14+'J17'!AW14+'J18'!AW14+'J19'!AW14+'J20'!AW14+'J21'!AW14+'J22'!AW14 -> 2 | AZ14: ='J1'!AX14+'J2'!AX14+'J3'!AX14+'J4'!AX14+'J5'!AX14+'J6'!AX14+'J7'!AX14+'J8'!AX14+'J9'!AX14+'J10'!AX14++'J11'!AX14+'J12'!AX14+'J13'!AX14+'J14'!AX14+'J15'!AX14+'J16'!AX14+'J17'!AX14+'J18'!AX14+'J19'!AX14+'J20'!AX14+'J21'!AX14+'J22'!AX14 -> 2 | BA14: ='J1'!AY14+'J2'!AY14+'J3'!AY14+'J4'!AY14+'J5'!AY14+'J6'!AY14+'J7'!AY14+'J8'!AY14+'J9'!AY14+'J10'!AY14++'J11'!AY14+'J12'!AY14+'J13'!AY14+'J14'!AY14+'J15'!AY14+'J16'!AY14+'J17'!AY14+'J18'!AY14+'J19'!AY14+'J20'!AY14+'J21'!AY14+'J22'!AY14 -> 0 | BB14: ='J1'!AZ14+'J2'!AZ14+'J3'!AZ14+'J4'!AZ14+'J5'!AZ14+'J6'!AZ14+'J7'!AZ14+'J8'!AZ14+'J9'!AZ14+'J10'!AZ14++'J11'!AZ14+'J12'!AZ14+'J13'!AZ14+'J14'!AZ14+'J15'!AZ14+'J16'!AZ14+'J17'!AZ14+'J18'!AZ14+'J19'!AZ14+'J20'!AZ14+'J21'!AZ14+'J22'!AZ14 -> 0 | BC14: ='J1'!BA14+'J2'!BA14+'J3'!BA14+'J4'!BA14+'J5'!BA14+'J6'!BA14+'J7'!BA14+'J8'!BA14+'J9'!BA14+'J10'!BA14++'J11'!BA14+'J12'!BA14+'J13'!BA14+'J14'!BA14+'J15'!BA14+'J16'!BA14+'J17'!BA14+'J18'!BA14+'J19'!BA14+'J20'!BA14+'J21'!BA14+'J22'!BA14 -> 0 | BD14: ='J1'!BB14+'J2'!BB14+'J3'!BB14+'J4'!BB14+'J5'!BB14+'J6'!BB14+'J7'!BB14+'J8'!BB14+'J9'!BB14+'J10'!BB14++'J11'!BB14+'J12'!BB14+'J13'!BB14+'J14'!BB14+'J15'!BB14+'J16'!BB14+'J17'!BB14+'J18'!BB14+'J19'!BB14+'J20'!BB14+'J21'!BB14+'J22'!BB14 -> 0 | BE14: ='J1'!BC14+'J2'!BC14+'J3'!BC14+'J4'!BC14+'J5'!BC14+'J6'!BC14+'J7'!BC14+'J8'!BC14+'J9'!BC14+'J10'!BC14++'J11'!BC14+'J12'!BC14+'J13'!BC14+'J14'!BC14+'J15'!BC14+'J16'!BC14+'J17'!BC14+'J18'!BC14+'J19'!BC14+'J20'!BC14+'J21'!BC14+'J22'!BC14 -> 0 | ... BI14: ='J1'!BG14+'J2'!BG14+'J3'!BG14+'J4'!BG14+'J5'!BG14+'J6'!BG14+'J7'!BG14+'J8'!BG14+'J9'!BG14+'J10'!BG14++'J11'!BG14+'J12'!BG14+'J13'!BG14+'J14'!BG14+'J15'!BG14+'J16'!BG14+'J17'!BG14+'J18'!BG14+'J19'!BG14+'J20'!BG14+'J21'!BG14+'J22'!BG14 -> 0
F15: JOEL | H15: 8 | I15: 1 | J15: =('J1'!I15+'J2'!I15+'J3'!I15+'J4'!I14+'J5'!I15+'J6'!I15+'J7'!I15+'J8'!I15+'J9'!I15+'J10'!I15++'J11'!I15+'J12'!I15+'J13'!I15+'J14'!I15+'J15'!I15+'J16'!I15+'J17'!I15+'J18'!I15+'J19'!I15+'J20'!I15+'J21'!I15+'J22'!I15)/H15 -> 38.75 | K15: =J15/60 -> 0.64583333 | L15: =('J1'!J15+'J2'!J15+'J3'!J15+'J4'!J15+'J5'!J15+'J6'!J15+'J7'!J15+'J8'!J15+'J9'!J15+'J10'!J15++'J11'!J15+'J12'!J15+'J13'!J15+'J14'!J15+'J15'!J15+'J16'!J15+'J17'!J15+'J18'!J15+'J19'!J15+'J20'!J15+'J21'!J15+'J22'!J15)/$C$3 -> 0 | M15: =('J1'!K15+'J2'!K15+'J3'!K15+'J4'!K15+'J5'!K15+'J6'!K15+'J7'!K15+'J8'!K15+'J9'!K15+'J10'!K15++'J11'!K15+'J12'!K15+'J13'!K15+'J14'!K15+'J15'!K15+'J16'!K15+'J17'!K15+'J18'!K15+'J19'!K15+'J20'!K15+'J21'!K15+'J22'!K15)/$C$3 -> 0 | N15: =('J1'!L15+'J2'!L15+'J3'!L15+'J4'!L15+'J5'!L15+'J6'!L15+'J7'!L15+'J8'!L15+'J9'!L15+'J10'!L15+'J11'!L15+'J12'!L15+'J13'!L15+'J14'!L15+'J15'!L15+'J16'!L15+'J17'!L15+'J18'!L15+'J19'!L15+'J20'!L15+'J21'!L15+'J22'!L15)/$C$3 -> 1.3333333 | O15: =IFERROR(Q15/P15,"") -> 0.64788732 | P15: =SUM(T15:X15)+SUM(AG15:AJ15)+SUM(AM15:AP15)+SUM(AA15:AD15) -> 71 | Q15: =T15+AG15+AM15+AA15 -> 46 | R15: =IF(SUM(T15:X15)=0,"",T15/SUM(T15:X15)) -> 0.51724138 | S15: =SUM(T15:X15) -> 29 | T15: ='J1'!R15+'J2'!R15+'J3'!R15+'J4'!R15+'J5'!R15+'J6'!R15+'J7'!R15+'J8'!R15+'J9'!R15+'J10'!R15++'J11'!R15+'J12'!R15+'J13'!R15+'J14'!R15+'J15'!R15+'J16'!R15+'J17'!R15+'J18'!R15+'J19'!R15+'J20'!R15+'J21'!R15+'J22'!R15 -> 15 | U15: ='J1'!S15+'J2'!S15+'J3'!S15+'J4'!S15+'J5'!S15+'J6'!S15+'J7'!S15+'J8'!S15+'J9'!S15+'J10'!S15++'J11'!S15+'J12'!S15+'J13'!S15+'J14'!S15+'J15'!S15+'J16'!S15+'J17'!S15+'J18'!S15+'J19'!S15+'J20'!S15+'J21'!S15+'J22'!S15 -> 6 | V15: ='J1'!T15+'J2'!T15+'J3'!T15+'J4'!T15+'J5'!T15+'J6'!T15+'J7'!T15+'J8'!T15+'J9'!T15+'J10'!T15++'J11'!T15+'J12'!T15+'J13'!T15+'J14'!T15+'J15'!T15+'J16'!T15+'J17'!T15+'J18'!T15+'J19'!T15+'J20'!T15+'J21'!T15+'J22'!T15 -> 4 | W15: ='J1'!U15+'J2'!U15+'J3'!U15+'J4'!U15+'J5'!U15+'J6'!U15+'J7'!U15+'J8'!U15+'J9'!U15+'J10'!U15++'J11'!U15+'J12'!U15+'J13'!U15+'J14'!U15+'J15'!U15+'J16'!U15+'J17'!U15+'J18'!U15+'J19'!U15+'J20'!U15+'J21'!U15+'J22'!U15 -> 4 | X15: ='J1'!V15+'J2'!V15+'J3'!V15+'J4'!V15+'J5'!V15+'J6'!V15+'J7'!V15+'J8'!V15+'J9'!V15+'J10'!V15++'J11'!V15+'J12'!V15+'J13'!V15+'J14'!V15+'J15'!V15+'J16'!V15+'J17'!V15+'J18'!V15+'J19'!V15+'J20'!V15+'J21'!V15+'J22'!V15 -> 0 | Y15: =IFERROR(AA15/SUM(AA15:AD15), "") -> 0.75 | Z15: =SUM(AA15:AD15) -> 4 | AA15: ='J1'!Y15+'J2'!Y15+'J3'!Y15+'J4'!Y15+'J5'!Y15+'J6'!Y15+'J7'!Y15+'J8'!Y15+'J9'!Y15+'J10'!Y15++'J11'!Y15+'J12'!Y15+'J13'!Y15+'J14'!Y15+'J15'!Y15+'J16'!Y15+'J17'!Y15+'J18'!Y15+'J19'!Y15+'J20'!Y15+'J21'!Y15+'J22'!Y15 -> 3 | AB15: ='J1'!Z15+'J2'!Z15+'J3'!Z15+'J4'!Z15+'J5'!Z15+'J6'!Z15+'J7'!Z15+'J8'!Z15+'J9'!Z15+'J10'!Z15++'J11'!Z15+'J12'!Z15+'J13'!Z15+'J14'!Z15+'J15'!Z15+'J16'!Z15+'J17'!Z15+'J18'!Z15+'J19'!Z15+'J20'!Z15+'J21'!Z15+'J22'!Z15 -> 0 | AC15: ='J1'!AA15+'J2'!AA15+'J3'!AA15+'J4'!AA15+'J5'!AA15+'J6'!AA15+'J7'!AA15+'J8'!AA15+'J9'!AA15+'J10'!AA15++'J11'!AA15+'J12'!AA15+'J13'!AA15+'J14'!AA15+'J15'!AA15+'J16'!AA15+'J17'!AA15+'J18'!AA15+'J19'!AA15+'J20'!AA15+'J21'!AA15+'J22'!AA15 -> 0 | AD15: ='J1'!AB15+'J2'!AB15+'J3'!AB15+'J4'!AB15+'J5'!AB15+'J6'!AB15+'J7'!AB15+'J8'!AB15+'J9'!AB15+'J10'!AB15++'J11'!AB15+'J12'!AB15+'J13'!AB15+'J14'!AB15+'J15'!AB15+'J16'!AB15+'J17'!AB15+'J18'!AB15+'J19'!AB15+'J20'!AB15+'J21'!AB15+'J22'!AB15 -> 1 | AE15: =IFERROR(AG15/SUM(AG15:AJ15), "") -> 0.73529412 | AF15: =SUM(AG15:AJ15) -> 34 | AG15: ='J1'!AE15+'J2'!AE15+'J3'!AE15+'J4'!AE15+'J5'!AE15+'J6'!AE15+'J7'!AE15+'J8'!AE15+'J9'!AE15+'J10'!AE15++'J11'!AE15+'J12'!AE15+'J13'!AE15+'J14'!AE15+'J15'!AE15+'J16'!AE15+'J17'!AE15+'J18'!AE15+'J19'!AE15+'J20'!AE15+'J21'!AE15+'J22'!AE15 -> 25 | AH15: ='J1'!AF15+'J2'!AF15+'J3'!AF15+'J4'!AF15+'J5'!AF15+'J6'!AF15+'J7'!AF15+'J8'!AF15+'J9'!AF15+'J10'!AF15++'J11'!AF15+'J12'!AF15+'J13'!AF15+'J14'!AF15+'J15'!AF15+'J16'!AF15+'J17'!AF15+'J18'!AF15+'J19'!AF15+'J20'!AF15+'J21'!AF15+'J22'!AF15 -> 3 | AI15: ='J1'!AG15+'J2'!AG15+'J3'!AG15+'J4'!AG15+'J5'!AG15+'J6'!AG15+'J7'!AG15+'J8'!AG15+'J9'!AG15+'J10'!AG15++'J11'!AG15+'J12'!AG15+'J13'!AG15+'J14'!AG15+'J15'!AG15+'J16'!AG15+'J17'!AG15+'J18'!AG15+'J19'!AG15+'J20'!AG15+'J21'!AG15+'J22'!AG15 -> 1 | AJ15: ='J1'!AH15+'J2'!AH15+'J3'!AH15+'J4'!AH15+'J5'!AH15+'J6'!AH15+'J7'!AH15+'J8'!AH15+'J9'!AH15+'J10'!AH15++'J11'!AH15+'J12'!AH15+'J13'!AH15+'J14'!AH15+'J15'!AH15+'J16'!AH15+'J17'!AH15+'J18'!AH15+'J19'!AH15+'J20'!AH15+'J21'!AH15+'J22'!AH15 -> 5 | AK15: =IFERROR(AM15/SUM(AM15:AP15), "") -> 0.75 | AL15: =SUM(AM15:AP15) -> 4 | AM15: ='J1'!AK15+'J2'!AK15+'J3'!AK15+'J4'!AK15+'J5'!AK15+'J6'!AK15+'J7'!AK15+'J8'!AK15+'J9'!AK15+'J10'!AK15++'J11'!AK15+'J12'!AK15+'J13'!AK15+'J14'!AK15+'J15'!AK15+'J16'!AK15+'J17'!AK15+'J18'!AK15+'J19'!AK15+'J20'!AK15+'J21'!AK15+'J22'!AK15 -> 3 | AN15: ='J1'!AL15+'J2'!AL15+'J3'!AL15+'J4'!AL15+'J5'!AL15+'J6'!AL15+'J7'!AL15+'J8'!AL15+'J9'!AL15+'J10'!AL15++'J11'!AL15+'J12'!AL15+'J13'!AL15+'J14'!AL15+'J15'!AL15+'J16'!AL15+'J17'!AL15+'J18'!AL15+'J19'!AL15+'J20'!AL15+'J21'!AL15+'J22'!AL15 -> 1 | AO15: ='J1'!AM15+'J2'!AM15+'J3'!AM15+'J4'!AM15+'J5'!AM15+'J6'!AM15+'J7'!AM15+'J8'!AM15+'J9'!AM15+'J10'!AM15++'J11'!AM15+'J12'!AM15+'J13'!AM15+'J14'!AM15+'J15'!AM15+'J16'!AM15+'J17'!AM15+'J18'!AM15+'J19'!AM15+'J20'!AM15+'J21'!AM15+'J22'!AM15 -> 0 | AP15: ='J1'!AN15+'J2'!AN15+'J3'!AN15+'J4'!AN15+'J5'!AN15+'J6'!AN15+'J7'!AN15+'J8'!AN15+'J9'!AN15+'J10'!AN15++'J11'!AN15+'J12'!AN15+'J13'!AN15+'J14'!AN15+'J15'!AN15+'J16'!AN15+'J17'!AN15+'J18'!AN15+'J19'!AN15+'J20'!AN15+'J21'!AN15+'J22'!AN15 -> 0 | AQ15: =SUM(AR15:AV15) -> 7 | AR15: ='J1'!AP15+'J2'!AP15+'J3'!AP15+'J4'!AP15+'J5'!AP15+'J6'!AP15+'J7'!AP15+'J8'!AP15+'J9'!AP15+'J10'!AP15++'J11'!AP15+'J12'!AP15+'J13'!AP15+'J14'!AP15+'J15'!AP15+'J16'!AP15+'J17'!AP15+'J18'!AP15+'J19'!AP15+'J20'!AP15+'J21'!AP15+'J22'!AP15 -> 0 | AS15: ='J1'!AQ15+'J2'!AQ15+'J3'!AQ15+'J4'!AQ15+'J5'!AQ15+'J6'!AQ15+'J7'!AQ15+'J8'!AQ15+'J9'!AQ15+'J10'!AQ15++'J11'!AQ15+'J12'!AQ15+'J13'!AQ15+'J14'!AQ15+'J15'!AQ15+'J16'!AQ15+'J17'!AQ15+'J18'!AQ15+'J19'!AQ15+'J20'!AQ15+'J21'!AQ15+'J22'!AQ15 -> 0 | AT15: ='J1'!AR15+'J2'!AR15+'J3'!AR15+'J4'!AR15+'J5'!AR15+'J6'!AR15+'J7'!AR15+'J8'!AR15+'J9'!AR15+'J10'!AR15++'J11'!AR15+'J12'!AR15+'J13'!AR15+'J14'!AR15+'J15'!AR15+'J16'!AR15+'J17'!AR15+'J18'!AR15+'J19'!AR15+'J20'!AR15+'J21'!AR15+'J22'!AR15 -> 5 | AU15: ='J1'!AS15+'J2'!AS15+'J3'!AS15+'J4'!AS15+'J5'!AS15+'J6'!AS15+'J7'!AS15+'J8'!AS15+'J9'!AS15+'J10'!AS15++'J11'!AS15+'J12'!AS15+'J13'!AS15+'J14'!AS15+'J15'!AS15+'J16'!AS15+'J17'!AS15+'J18'!AS15+'J19'!AS15+'J20'!AS15+'J21'!AS15+'J22'!AS15 -> 1 | AV15: ='J1'!AT15+'J2'!AT15+'J3'!AT15+'J4'!AT15+'J5'!AT15+'J6'!AT15+'J7'!AT15+'J8'!AT15+'J9'!AT15+'J10'!AT15++'J11'!AT15+'J12'!AT15+'J13'!AT15+'J14'!AT15+'J15'!AT15+'J16'!AT15+'J17'!AT15+'J18'!AT15+'J19'!AT15+'J20'!AT15+'J21'!AT15+'J22'!AT15 -> 1 | AW15: =AX15+AY15+AZ15+BA15+BB15+BC15+BD15+0.5*BE15+BF15+BG15+2*BH15+2*BI15 -> 13 | AX15: ='J1'!AV15+'J2'!AV15+'J3'!AV15+'J4'!AV15+'J5'!AV15+'J6'!AV15+'J7'!AV15+'J8'!AV15+'J9'!AV15+'J10'!AV15++'J11'!AV15+'J12'!AV15+'J13'!AV15+'J14'!AV15+'J15'!AV15+'J16'!AV15+'J17'!AV15+'J18'!AV15+'J19'!AV15+'J20'!AV15+'J21'!AV15+'J22'!AV15 -> 9 | AY15: ='J1'!AW15+'J2'!AW15+'J3'!AW15+'J4'!AW15+'J5'!AW15+'J6'!AW15+'J7'!AW15+'J8'!AW15+'J9'!AW15+'J10'!AW15++'J11'!AW15+'J12'!AW15+'J13'!AW15+'J14'!AW15+'J15'!AW15+'J16'!AW15+'J17'!AW15+'J18'!AW15+'J19'!AW15+'J20'!AW15+'J21'!AW15+'J22'!AW15 -> 0 | AZ15: ='J1'!AX15+'J2'!AX15+'J3'!AX15+'J4'!AX15+'J5'!AX15+'J6'!AX15+'J7'!AX15+'J8'!AX15+'J9'!AX15+'J10'!AX15++'J11'!AX15+'J12'!AX15+'J13'!AX15+'J14'!AX15+'J15'!AX15+'J16'!AX15+'J17'!AX15+'J18'!AX15+'J19'!AX15+'J20'!AX15+'J21'!AX15+'J22'!AX15 -> 0 | BA15: ='J1'!AY15+'J2'!AY15+'J3'!AY15+'J4'!AY15+'J5'!AY15+'J6'!AY15+'J7'!AY15+'J8'!AY15+'J9'!AY15+'J10'!AY15++'J11'!AY15+'J12'!AY15+'J13'!AY15+'J14'!AY15+'J15'!AY15+'J16'!AY15+'J17'!AY15+'J18'!AY15+'J19'!AY15+'J20'!AY15+'J21'!AY15+'J22'!AY15 -> 1 | BB15: ='J1'!AZ15+'J2'!AZ15+'J3'!AZ15+'J4'!AZ15+'J5'!AZ15+'J6'!AZ15+'J7'!AZ15+'J8'!AZ15+'J9'!AZ15+'J10'!AZ15++'J11'!AZ15+'J12'!AZ15+'J13'!AZ15+'J14'!AZ15+'J15'!AZ15+'J16'!AZ15+'J17'!AZ15+'J18'!AZ15+'J19'!AZ15+'J20'!AZ15+'J21'!AZ15+'J22'!AZ15 -> 2 | BC15: ='J1'!BA15+'J2'!BA15+'J3'!BA15+'J4'!BA15+'J5'!BA15+'J6'!BA15+'J7'!BA15+'J8'!BA15+'J9'!BA15+'J10'!BA15++'J11'!BA15+'J12'!BA15+'J13'!BA15+'J14'!BA15+'J15'!BA15+'J16'!BA15+'J17'!BA15+'J18'!BA15+'J19'!BA15+'J20'!BA15+'J21'!BA15+'J22'!BA15 -> 0 | BD15: ='J1'!BB15+'J2'!BB15+'J3'!BB15+'J4'!BB15+'J5'!BB15+'J6'!BB15+'J7'!BB15+'J8'!BB15+'J9'!BB15+'J10'!BB15++'J11'!BB15+'J12'!BB15+'J13'!BB15+'J14'!BB15+'J15'!BB15+'J16'!BB15+'J17'!BB15+'J18'!BB15+'J19'!BB15+'J20'!BB15+'J21'!BB15+'J22'!BB15 -> 0 | BE15: ='J1'!BC15+'J2'!BC15+'J3'!BC15+'J4'!BC15+'J5'!BC15+'J6'!BC15+'J7'!BC15+'J8'!BC15+'J9'!BC15+'J10'!BC15++'J11'!BC15+'J12'!BC15+'J13'!BC15+'J14'!BC15+'J15'!BC15+'J16'!BC15+'J17'!BC15+'J18'!BC15+'J19'!BC15+'J20'!BC15+'J21'!BC15+'J22'!BC15 -> 0 | ... BI15: ='J1'!BG15+'J2'!BG15+'J3'!BG15+'J4'!BG15+'J5'!BG15+'J6'!BG15+'J7'!BG15+'J8'!BG15+'J9'!BG15+'J10'!BG15++'J11'!BG15+'J12'!BG15+'J13'!BG15+'J14'!BG15+'J15'!BG15+'J16'!BG15+'J17'!BG15+'J18'!BG15+'J19'!BG15+'J20'!BG15+'J21'!BG15+'J22'!BG15 -> 0
